Workbook

Sheet 메인표지
A12: 건설안전기술사 과년도 출제문제 분석
H14: (106회~137회)

Sheet 집계 및 분석
A1: □ 최근 건설안전기술사 과년도 출제 분석(106회~137회) | O1: =E3
A2: NO | B2: 분류 | C2: 합계 | F2: 137 | G2: 136 | H2: 135 | I2: 134 | J2: 133 | K2: 132 | L2: 131 | M2: 130 | N2: 129 | O2: 128 | P2: 127 | Q2: 126 | R2: 125 | S2: 124 | T2: 123 | U2: 122 | V2: 121 | W2: 120 | X2: 119 | Y2: 118 | Z2: 117 | AA2: 116 | AB2: 115 | AC2: 114 | AD2: 113 | AE2: 112 | AF2: 111 | AG2: 110 | AH2: 109 | AI2: 108 | AJ2: 107 | AK2: 106 | AL2: 비고
A3: 1 | B3: 산업안전보건법 | C3: =SUM(E3:AK3) | F3: =COUNTIFS(과년도모음!$B:$B,F$2,과년도모음!$E:$E,"산안법") | G3: =COUNTIFS(과년도모음!$B:$B,G$2,과년도모음!$E:$E,"산안법") | H3: =COUNTIFS(과년도모음!$B:$B,H$2,과년도모음!$E:$E,"산안법") | I3: =COUNTIFS(과년도모음!$B:$B,I$2,과년도모음!$E:$E,"산안법") | J3: =COUNTIFS(과년도모음!$B:$B,J$2,과년도모음!$E:$E,"산안법") | K3: =COUNTIFS(과년도모음!$B:$B,K$2,과년도모음!$E:$E,"산안법") | L3: =COUNTIFS(과년도모음!$B$1:$B$1024,L$2,과년도모음!$E$1:$E$1024,"산안법") | M3: =COUNTIFS(과년도모음!$B$1:$B$1024,M$2,과년도모음!$E$1:$E$1024,"산안법") | N3: =COUNTIFS(과년도모음!$B$281:$B$1024,N$2,과년도모음!$E$281:$E$1024,"산안법") | O3: =COUNTIFS(과년도모음!$B$312:$B$1024,O$2,과년도모음!$E$312:$E$1024,"산안법") | P3: =COUNTIFS(과년도모음!$B$343:$B$1024,P$2,과년도모음!$E$343:$E$1024,"산안법") | Q3: =COUNTIFS(과년도모음!$B$343:$B$1024,Q$2,과년도모음!$E$343:$E$1024,"산안법") | R3: =COUNTIFS(과년도모음!$B$343:$B$1024,R$2,과년도모음!$E$343:$E$1024,"산안법") | S3: =COUNTIFS(과년도모음!$B$343:$B$1024,S$2,과년도모음!$E$343:$E$1024,"산안법") | T3: =COUNTIFS(과년도모음!$B$343:$B$1024,T$2,과년도모음!$E$343:$E$1024,"산안법") | U3: =COUNTIFS(과년도모음!$B$343:$B$1024,U$2,과년도모음!$E$343:$E$1024,"산안법") | V3: =COUNTIFS(과년도모음!$B$343:$B$1024,V$2,과년도모음!$E$343:$E$1024,"산안법") | W3: =COUNTIFS(과년도모음!$B$343:$B$1024,W$2,과년도모음!$E$343:$E$1024,"산안법") | ... AK3: =COUNTIFS(과년도모음!$B$343:$B$1024,AK$2,과년도모음!$E$343:$E$1024,"산안법")
A4: 2 | B4: 건설기술진흥법 | C4: =SUM(E4:AK4) | F4: =COUNTIFS(과년도모음!$B$1:$B$1024,F$2,과년도모음!$E$1:$E$1024,"건진법") | G4: =COUNTIFS(과년도모음!$B$1:$B$1024,G$2,과년도모음!$E$1:$E$1024,"건진법") | H4: =COUNTIFS(과년도모음!$B$1:$B$1024,H$2,과년도모음!$E$1:$E$1024,"건진법") | I4: =COUNTIFS(과년도모음!$B$1:$B$1024,I$2,과년도모음!$E$1:$E$1024,"건진법") | J4: =COUNTIFS(과년도모음!$B$1:$B$1024,J$2,과년도모음!$E$1:$E$1024,"건진법") | K4: =COUNTIFS(과년도모음!$B$1:$B$1024,K$2,과년도모음!$E$1:$E$1024,"건진법") | L4: =COUNTIFS(과년도모음!$B$1:$B$1024,L$2,과년도모음!$E$1:$E$1024,"건진법") | M4: =COUNTIFS(과년도모음!$B$1:$B$1024,M$2,과년도모음!$E$1:$E$1024,"건진법") | N4: =COUNTIFS(과년도모음!$B$281:$B$1024,N$2,과년도모음!$E$281:$E$1024,"건진법") | O4: =COUNTIFS(과년도모음!$B$312:$B$1024,O$2,과년도모음!$E$312:$E$1024,"건진법") | P4: =COUNTIFS(과년도모음!$B$343:$B$1024,P$2,과년도모음!$E$343:$E$1024,"건진법") | Q4: =COUNTIFS(과년도모음!$B$343:$B$1024,Q$2,과년도모음!$E$343:$E$1024,"건진법") | R4: =COUNTIFS(과년도모음!$B$343:$B$1024,R$2,과년도모음!$E$343:$E$1024,"건진법") | S4: =COUNTIFS(과년도모음!$B$343:$B$1024,S$2,과년도모음!$E$343:$E$1024,"건진법") | T4: =COUNTIFS(과년도모음!$B$343:$B$1024,T$2,과년도모음!$E$343:$E$1024,"건진법") | U4: =COUNTIFS(과년도모음!$B$343:$B$1024,U$2,과년도모음!$E$343:$E$1024,"건진법") | V4: =COUNTIFS(과년도모음!$B$343:$B$1024,V$2,과년도모음!$E$343:$E$1024,"건진법") | W4: =COUNTIFS(과년도모음!$B$343:$B$1024,W$2,과년도모음!$E$343:$E$1024,"건진법") | ... AK4: =COUNTIFS(과년도모음!$B$343:$B$1024,AK$2,과년도모음!$E$343:$E$1024,"건진법")
A5: 3 | B5: 시설물안전법 | C5: =SUM(E5:AK5) | F5: =COUNTIFS(과년도모음!$B$1:$B$1024,F$2,과년도모음!$E$1:$E$1024,"시설물안전법") | G5: =COUNTIFS(과년도모음!$B$1:$B$1024,G$2,과년도모음!$E$1:$E$1024,"시설물안전법") | H5: =COUNTIFS(과년도모음!$B$1:$B$1024,H$2,과년도모음!$E$1:$E$1024,"시설물안전법") | I5: =COUNTIFS(과년도모음!$B$1:$B$1024,I$2,과년도모음!$E$1:$E$1024,"시설물안전법") | J5: =COUNTIFS(과년도모음!$B$1:$B$1024,J$2,과년도모음!$E$1:$E$1024,"시설물안전법") | K5: =COUNTIFS(과년도모음!$B$1:$B$1024,K$2,과년도모음!$E$1:$E$1024,"시설물안전법") | L5: =COUNTIFS(과년도모음!$B$1:$B$1024,L$2,과년도모음!$E$1:$E$1024,"시설물안전법") | M5: =COUNTIFS(과년도모음!$B$1:$B$1024,M$2,과년도모음!$E$1:$E$1024,"시설물안전법") | N5: =COUNTIFS(과년도모음!$B$281:$B$1024,N$2,과년도모음!$E$281:$E$1024,"시설물안전법") | O5: =COUNTIFS(과년도모음!$B$312:$B$1024,O$2,과년도모음!$E$312:$E$1024,"시설물안전법") | P5: =COUNTIFS(과년도모음!$B$343:$B$1024,P$2,과년도모음!$E$343:$E$1024,"시설물안전법") | Q5: =COUNTIFS(과년도모음!$B$343:$B$1024,Q$2,과년도모음!$E$343:$E$1024,"시설물안전법") | R5: =COUNTIFS(과년도모음!$B$343:$B$1024,R$2,과년도모음!$E$343:$E$1024,"시설물안전법") | S5: =COUNTIFS(과년도모음!$B$343:$B$1024,S$2,과년도모음!$E$343:$E$1024,"시설물안전법") | T5: =COUNTIFS(과년도모음!$B$343:$B$1024,T$2,과년도모음!$E$343:$E$1024,"시설물안전법") | U5: =COUNTIFS(과년도모음!$B$343:$B$1024,U$2,과년도모음!$E$343:$E$1024,"시설물안전법") | V5: =COUNTIFS(과년도모음!$B$343:$B$1024,V$2,과년도모음!$E$343:$E$1024,"시설물안전법") | W5: =COUNTIFS(과년도모음!$B$343:$B$1024,W$2,과년도모음!$E$343:$E$1024,"시설물안전법") | ... AK5: =COUNTIFS(과년도모음!$B$343:$B$1024,AK$2,과년도모음!$E$343:$E$1024,"시설물안전법")
A6: 4 | B6: 중대재해처벌법 | C6: =SUM(E6:AK6) | F6: =COUNTIFS(과년도모음!$B$1:$B$1024,F$2,과년도모음!$E$1:$E$1024,"중대재해처벌법") | G6: =COUNTIFS(과년도모음!$B$1:$B$1024,G$2,과년도모음!$E$1:$E$1024,"중대재해처벌법") | H6: =COUNTIFS(과년도모음!$B$1:$B$1024,H$2,과년도모음!$E$1:$E$1024,"중대재해처벌법") | I6: =COUNTIFS(과년도모음!$B$1:$B$1024,I$2,과년도모음!$E$1:$E$1024,"중대재해처벌법") | J6: =COUNTIFS(과년도모음!$B$1:$B$1024,J$2,과년도모음!$E$1:$E$1024,"중대재해처벌법") | K6: =COUNTIFS(과년도모음!$B$1:$B$1024,K$2,과년도모음!$E$1:$E$1024,"중대재해처벌법") | L6: =COUNTIFS(과년도모음!$B$1:$B$1024,L$2,과년도모음!$E$1:$E$1024,"중대재해처벌법") | M6: =COUNTIFS(과년도모음!$B$1:$B$1024,M$2,과년도모음!$E$1:$E$1024,"중대재해처벌법") | N6: =COUNTIFS(과년도모음!$B$281:$B$1024,N$2,과년도모음!$E$281:$E$1024,"중대재해처벌법") | O6: =COUNTIFS(과년도모음!$B$312:$B$1024,O$2,과년도모음!$E$312:$E$1024,"중대재해처벌법") | P6: =COUNTIFS(과년도모음!$B$343:$B$1024,P$2,과년도모음!$E$343:$E$1024,"중대재해처벌법") | Q6: =COUNTIFS(과년도모음!$B$343:$B$1024,Q$2,과년도모음!$E$343:$E$1024,"중대재해처벌법") | R6: =COUNTIFS(과년도모음!$B$343:$B$1024,R$2,과년도모음!$E$343:$E$1024,"중대재해처벌법") | S6: =COUNTIFS(과년도모음!$B$343:$B$1024,S$2,과년도모음!$E$343:$E$1024,"중대재해처벌법") | T6: =COUNTIFS(과년도모음!$B$343:$B$1024,T$2,과년도모음!$E$343:$E$1024,"중대재해처벌법") | U6: =COUNTIFS(과년도모음!$B$343:$B$1024,U$2,과년도모음!$E$343:$E$1024,"중대재해처벌법") | V6: =COUNTIFS(과년도모음!$B$343:$B$1024,V$2,과년도모음!$E$343:$E$1024,"중대재해처벌법") | W6: =COUNTIFS(과년도모음!$B$343:$B$1024,W$2,과년도모음!$E$343:$E$1024,"중대재해처벌법") | ... AK6: =COUNTIFS(과년도모음!$B$343:$B$1024,AK$2,과년도모음!$E$343:$E$1024,"중대재해처벌법")
A7: 5 | B7: 지특법 | C7: =SUM(E7:AK7) | F7: =COUNTIFS(과년도모음!$B$1:$B$1024,F$2,과년도모음!$E$1:$E$1024,"지특법") | G7: =COUNTIFS(과년도모음!$B$1:$B$1024,G$2,과년도모음!$E$1:$E$1024,"지특법") | H7: =COUNTIFS(과년도모음!$B$1:$B$1024,H$2,과년도모음!$E$1:$E$1024,"지특법") | I7: =COUNTIFS(과년도모음!$B$1:$B$1024,I$2,과년도모음!$E$1:$E$1024,"지특법") | J7: =COUNTIFS(과년도모음!$B$1:$B$1024,J$2,과년도모음!$E$1:$E$1024,"지특법") | K7: =COUNTIFS(과년도모음!$B$1:$B$1024,K$2,과년도모음!$E$1:$E$1024,"지특법") | L7: =COUNTIFS(과년도모음!$B$1:$B$1024,L$2,과년도모음!$E$1:$E$1024,"지특법") | M7: =COUNTIFS(과년도모음!$B$1:$B$1024,M$2,과년도모음!$E$1:$E$1024,"지특법") | N7: =COUNTIFS(과년도모음!$B$281:$B$1024,N$2,과년도모음!$E$281:$E$1024,"지특법") | O7: =COUNTIFS(과년도모음!$B$312:$B$1024,O$2,과년도모음!$E$312:$E$1024,"지특법") | P7: =COUNTIFS(과년도모음!$B$343:$B$1024,P$2,과년도모음!$E$343:$E$1024,"지특법") | Q7: =COUNTIFS(과년도모음!$B$343:$B$1024,Q$2,과년도모음!$E$343:$E$1024,"지특법") | R7: =COUNTIFS(과년도모음!$B$343:$B$1024,R$2,과년도모음!$E$343:$E$1024,"지특법") | S7: =COUNTIFS(과년도모음!$B$343:$B$1024,S$2,과년도모음!$E$343:$E$1024,"지특법") | T7: =COUNTIFS(과년도모음!$B$343:$B$1024,T$2,과년도모음!$E$343:$E$1024,"지특법") | U7: =COUNTIFS(과년도모음!$B$343:$B$1024,U$2,과년도모음!$E$343:$E$1024,"지특법") | V7: =COUNTIFS(과년도모음!$B$343:$B$1024,V$2,과년도모음!$E$343:$E$1024,"지특법") | W7: =COUNTIFS(과년도모음!$B$343:$B$1024,W$2,과년도모음!$E$343:$E$1024,"지특법") | ... AK7: =COUNTIFS(과년도모음!$B$343:$B$1024,AK$2,과년도모음!$E$343:$E$1024,"지특법")
A8: 6 | B8: 가설공사 | C8: =SUM(E8:AK8) | F8: =COUNTIFS(과년도모음!$B$1:$B$1024,F$2,과년도모음!$E$1:$E$1024,"가설공사") | G8: =COUNTIFS(과년도모음!$B$1:$B$1024,G$2,과년도모음!$E$1:$E$1024,"가설공사") | H8: =COUNTIFS(과년도모음!$B$1:$B$1024,H$2,과년도모음!$E$1:$E$1024,"가설공사") | I8: =COUNTIFS(과년도모음!$B$1:$B$1024,I$2,과년도모음!$E$1:$E$1024,"가설공사") | J8: =COUNTIFS(과년도모음!$B$1:$B$1024,J$2,과년도모음!$E$1:$E$1024,"가설공사") | K8: =COUNTIFS(과년도모음!$B$1:$B$1024,K$2,과년도모음!$E$1:$E$1024,"가설공사") | L8: =COUNTIFS(과년도모음!$B$1:$B$1024,L$2,과년도모음!$E$1:$E$1024,"가설공사") | M8: =COUNTIFS(과년도모음!$B$1:$B$1024,M$2,과년도모음!$E$1:$E$1024,"가설공사") | N8: =COUNTIFS(과년도모음!$B$281:$B$1024,N$2,과년도모음!$E$281:$E$1024,"가설공사") | O8: =COUNTIFS(과년도모음!$B$312:$B$1024,O$2,과년도모음!$E$312:$E$1024,"가설공사") | P8: =COUNTIFS(과년도모음!$B$343:$B$1024,P$2,과년도모음!$E$343:$E$1024,"가설공사") | Q8: =COUNTIFS(과년도모음!$B$343:$B$1024,Q$2,과년도모음!$E$343:$E$1024,"가설공사") | R8: =COUNTIFS(과년도모음!$B$343:$B$1024,R$2,과년도모음!$E$343:$E$1024,"가설공사") | S8: =COUNTIFS(과년도모음!$B$343:$B$1024,S$2,과년도모음!$E$343:$E$1024,"가설공사") | T8: =COUNTIFS(과년도모음!$B$343:$B$1024,T$2,과년도모음!$E$343:$E$1024,"가설공사") | U8: =COUNTIFS(과년도모음!$B$343:$B$1024,U$2,과년도모음!$E$343:$E$1024,"가설공사") | V8: =COUNTIFS(과년도모음!$B$343:$B$1024,V$2,과년도모음!$E$343:$E$1024,"가설공사") | W8: =COUNTIFS(과년도모음!$B$343:$B$1024,W$2,과년도모음!$E$343:$E$1024,"가설공사") | ... AK8: =COUNTIFS(과년도모음!$B$343:$B$1024,AK$2,과년도모음!$E$343:$E$1024,"가설공사")
A9: 7 | B9: 건설기계 | C9: =SUM(E9:AK9) | F9: =COUNTIFS(과년도모음!$B$1:$B$1024,F$2,과년도모음!$E$1:$E$1024,"건설기계") | G9: =COUNTIFS(과년도모음!$B$1:$B$1024,G$2,과년도모음!$E$1:$E$1024,"건설기계") | H9: =COUNTIFS(과년도모음!$B$1:$B$1024,H$2,과년도모음!$E$1:$E$1024,"건설기계") | I9: =COUNTIFS(과년도모음!$B$1:$B$1024,I$2,과년도모음!$E$1:$E$1024,"건설기계") | J9: =COUNTIFS(과년도모음!$B$1:$B$1024,J$2,과년도모음!$E$1:$E$1024,"건설기계") | K9: =COUNTIFS(과년도모음!$B$1:$B$1024,K$2,과년도모음!$E$1:$E$1024,"건설기계") | L9: =COUNTIFS(과년도모음!$B$1:$B$1024,L$2,과년도모음!$E$1:$E$1024,"건설기계") | M9: =COUNTIFS(과년도모음!$B$1:$B$1024,M$2,과년도모음!$E$1:$E$1024,"건설기계") | N9: =COUNTIFS(과년도모음!$B$281:$B$1024,N$2,과년도모음!$E$281:$E$1024,"건설기계") | O9: =COUNTIFS(과년도모음!$B$312:$B$1024,O$2,과년도모음!$E$312:$E$1024,"건설기계") | P9: =COUNTIFS(과년도모음!$B$343:$B$1024,P$2,과년도모음!$E$343:$E$1024,"건설기계") | Q9: =COUNTIFS(과년도모음!$B$343:$B$1024,Q$2,과년도모음!$E$343:$E$1024,"건설기계") | R9: =COUNTIFS(과년도모음!$B$343:$B$1024,R$2,과년도모음!$E$343:$E$1024,"건설기계") | S9: =COUNTIFS(과년도모음!$B$343:$B$1024,S$2,과년도모음!$E$343:$E$1024,"건설기계") | T9: =COUNTIFS(과년도모음!$B$343:$B$1024,T$2,과년도모음!$E$343:$E$1024,"건설기계") | U9: =COUNTIFS(과년도모음!$B$343:$B$1024,U$2,과년도모음!$E$343:$E$1024,"건설기계") | V9: =COUNTIFS(과년도모음!$B$343:$B$1024,V$2,과년도모음!$E$343:$E$1024,"건설기계") | W9: =COUNTIFS(과년도모음!$B$343:$B$1024,W$2,과년도모음!$E$343:$E$1024,"건설기계") | ... AK9: =COUNTIFS(과년도모음!$B$343:$B$1024,AK$2,과년도모음!$E$343:$E$1024,"건설기계")
A10: 8 | B10: 안전관리론 | C10: =SUM(E10:AK10) | F10: =COUNTIFS(과년도모음!$B$1:$B$1024,F$2,과년도모음!$E$1:$E$1024,"안전관리론") | G10: =COUNTIFS(과년도모음!$B$1:$B$1024,G$2,과년도모음!$E$1:$E$1024,"안전관리론") | H10: =COUNTIFS(과년도모음!$B$1:$B$1024,H$2,과년도모음!$E$1:$E$1024,"안전관리론") | I10: =COUNTIFS(과년도모음!$B$1:$B$1024,I$2,과년도모음!$E$1:$E$1024,"안전관리론") | J10: =COUNTIFS(과년도모음!$B$1:$B$1024,J$2,과년도모음!$E$1:$E$1024,"안전관리론") | K10: =COUNTIFS(과년도모음!$B$1:$B$1024,K$2,과년도모음!$E$1:$E$1024,"안전관리론") | L10: =COUNTIFS(과년도모음!$B$1:$B$1024,L$2,과년도모음!$E$1:$E$1024,"안전관리론") | M10: =COUNTIFS(과년도모음!$B$1:$B$1024,M$2,과년도모음!$E$1:$E$1024,"안전관리론") | N10: =COUNTIFS(과년도모음!$B$281:$B$1024,N$2,과년도모음!$E$281:$E$1024,"안전관리론") | O10: =COUNTIFS(과년도모음!$B$312:$B$1024,O$2,과년도모음!$E$312:$E$1024,"안전관리론") | P10: =COUNTIFS(과년도모음!$B$343:$B$1024,P$2,과년도모음!$E$343:$E$1024,"안전관리론") | Q10: =COUNTIFS(과년도모음!$B$343:$B$1024,Q$2,과년도모음!$E$343:$E$1024,"안전관리론") | R10: =COUNTIFS(과년도모음!$B$343:$B$1024,R$2,과년도모음!$E$343:$E$1024,"안전관리론") | S10: =COUNTIFS(과년도모음!$B$343:$B$1024,S$2,과년도모음!$E$343:$E$1024,"안전관리론") | T10: =COUNTIFS(과년도모음!$B$343:$B$1024,T$2,과년도모음!$E$343:$E$1024,"안전관리론") | U10: =COUNTIFS(과년도모음!$B$343:$B$1024,U$2,과년도모음!$E$343:$E$1024,"안전관리론") | V10: =COUNTIFS(과년도모음!$B$343:$B$1024,V$2,과년도모음!$E$343:$E$1024,"안전관리론") | W10: =COUNTIFS(과년도모음!$B$343:$B$1024,W$2,과년도모음!$E$343:$E$1024,"안전관리론") | ... AK10: =COUNTIFS(과년도모음!$B$343:$B$1024,AK$2,과년도모음!$E$343:$E$1024,"안전관리론")
A11: 9 | B11: 재해유형 | C11: =SUM(E11:AK11) | F11: =COUNTIFS(과년도모음!$B$1:$B$1024,F$2,과년도모음!$E$1:$E$1024,"재해유형") | G11: =COUNTIFS(과년도모음!$B$1:$B$1024,G$2,과년도모음!$E$1:$E$1024,"재해유형") | H11: =COUNTIFS(과년도모음!$B$1:$B$1024,H$2,과년도모음!$E$1:$E$1024,"재해유형") | I11: =COUNTIFS(과년도모음!$B$1:$B$1024,I$2,과년도모음!$E$1:$E$1024,"재해유형") | J11: =COUNTIFS(과년도모음!$B$1:$B$1024,J$2,과년도모음!$E$1:$E$1024,"재해유형") | K11: =COUNTIFS(과년도모음!$B$1:$B$1024,K$2,과년도모음!$E$1:$E$1024,"재해유형") | L11: =COUNTIFS(과년도모음!$B$1:$B$1024,L$2,과년도모음!$E$1:$E$1024,"재해유형") | M11: =COUNTIFS(과년도모음!$B$1:$B$1024,M$2,과년도모음!$E$1:$E$1024,"재해유형") | N11: =COUNTIFS(과년도모음!$B$281:$B$1024,N$2,과년도모음!$E$281:$E$1024,"재해유형") | O11: =COUNTIFS(과년도모음!$B$312:$B$1024,O$2,과년도모음!$E$312:$E$1024,"재해유형") | P11: =COUNTIFS(과년도모음!$B$343:$B$1024,P$2,과년도모음!$E$343:$E$1024,"재해유형") | Q11: =COUNTIFS(과년도모음!$B$343:$B$1024,Q$2,과년도모음!$E$343:$E$1024,"재해유형") | R11: =COUNTIFS(과년도모음!$B$343:$B$1024,R$2,과년도모음!$E$343:$E$1024,"재해유형") | S11: =COUNTIFS(과년도모음!$B$343:$B$1024,S$2,과년도모음!$E$343:$E$1024,"재해유형") | T11: =COUNTIFS(과년도모음!$B$343:$B$1024,T$2,과년도모음!$E$343:$E$1024,"재해유형") | U11: =COUNTIFS(과년도모음!$B$343:$B$1024,U$2,과년도모음!$E$343:$E$1024,"재해유형") | V11: =COUNTIFS(과년도모음!$B$343:$B$1024,V$2,과년도모음!$E$343:$E$1024,"재해유형") | W11: =COUNTIFS(과년도모음!$B$343:$B$1024,W$2,과년도모음!$E$343:$E$1024,"재해유형") | ... AK11: =COUNTIFS(과년도모음!$B$343:$B$1024,AK$2,과년도모음!$E$343:$E$1024,"재해유형")
A12: 10 | B12: 계절재해 | C12: =SUM(E12:AK12) | F12: =COUNTIFS(과년도모음!$B$1:$B$1024,F$2,과년도모음!$E$1:$E$1024,"계절재해") | G12: =COUNTIFS(과년도모음!$B$1:$B$1024,G$2,과년도모음!$E$1:$E$1024,"계절재해") | H12: =COUNTIFS(과년도모음!$B$1:$B$1024,H$2,과년도모음!$E$1:$E$1024,"계절재해") | I12: =COUNTIFS(과년도모음!$B$1:$B$1024,I$2,과년도모음!$E$1:$E$1024,"계절재해") | J12: =COUNTIFS(과년도모음!$B$1:$B$1024,J$2,과년도모음!$E$1:$E$1024,"계절재해") | K12: =COUNTIFS(과년도모음!$B$1:$B$1024,K$2,과년도모음!$E$1:$E$1024,"계절재해") | L12: =COUNTIFS(과년도모음!$B$1:$B$1024,L$2,과년도모음!$E$1:$E$1024,"계절재해") | M12: =COUNTIFS(과년도모음!$B$1:$B$1024,M$2,과년도모음!$E$1:$E$1024,"계절재해") | N12: =COUNTIFS(과년도모음!$B$281:$B$1024,N$2,과년도모음!$E$281:$E$1024,"계절재해") | O12: =COUNTIFS(과년도모음!$B$312:$B$1024,O$2,과년도모음!$E$312:$E$1024,"계절재해") | P12: =COUNTIFS(과년도모음!$B$343:$B$1024,P$2,과년도모음!$E$343:$E$1024,"계절재해") | Q12: =COUNTIFS(과년도모음!$B$343:$B$1024,Q$2,과년도모음!$E$343:$E$1024,"계절재해") | R12: =COUNTIFS(과년도모음!$B$343:$B$1024,R$2,과년도모음!$E$343:$E$1024,"계절재해") | S12: =COUNTIFS(과년도모음!$B$343:$B$1024,S$2,과년도모음!$E$343:$E$1024,"계절재해") | T12: =COUNTIFS(과년도모음!$B$343:$B$1024,T$2,과년도모음!$E$343:$E$1024,"계절재해") | U12: =COUNTIFS(과년도모음!$B$343:$B$1024,U$2,과년도모음!$E$343:$E$1024,"계절재해") | V12: =COUNTIFS(과년도모음!$B$343:$B$1024,V$2,과년도모음!$E$343:$E$1024,"계절재해") | W12: =COUNTIFS(과년도모음!$B$343:$B$1024,W$2,과년도모음!$E$343:$E$1024,"계절재해") | ... AK12: =COUNTIFS(과년도모음!$B$343:$B$1024,AK$2,과년도모음!$E$343:$E$1024,"계절재해")
A13: 11 | B13: 콘크리트(거푸집 동바리 철근 포함) | C13: =SUM(E13:AK13) | F13: =COUNTIFS(과년도모음!$B$1:$B$1024,F$2,과년도모음!$E$1:$E$1024,"콘크리트") | G13: =COUNTIFS(과년도모음!$B$1:$B$1024,G$2,과년도모음!$E$1:$E$1024,"콘크리트") | H13: =COUNTIFS(과년도모음!$B$1:$B$1024,H$2,과년도모음!$E$1:$E$1024,"콘크리트") | I13: =COUNTIFS(과년도모음!$B$1:$B$1024,I$2,과년도모음!$E$1:$E$1024,"콘크리트") | J13: =COUNTIFS(과년도모음!$B$1:$B$1024,J$2,과년도모음!$E$1:$E$1024,"콘크리트") | K13: =COUNTIFS(과년도모음!$B$1:$B$1024,K$2,과년도모음!$E$1:$E$1024,"콘크리트") | L13: =COUNTIFS(과년도모음!$B$1:$B$1024,L$2,과년도모음!$E$1:$E$1024,"콘크리트") | M13: =COUNTIFS(과년도모음!$B$1:$B$1024,M$2,과년도모음!$E$1:$E$1024,"콘크리트") | N13: =COUNTIFS(과년도모음!$B$281:$B$1024,N$2,과년도모음!$E$281:$E$1024,"콘크리트") | O13: =COUNTIFS(과년도모음!$B$312:$B$1024,O$2,과년도모음!$E$312:$E$1024,"콘크리트") | P13: =COUNTIFS(과년도모음!$B$343:$B$1024,P$2,과년도모음!$E$343:$E$1024,"콘크리트") | Q13: =COUNTIFS(과년도모음!$B$343:$B$1024,Q$2,과년도모음!$E$343:$E$1024,"콘크리트") | R13: =COUNTIFS(과년도모음!$B$343:$B$1024,R$2,과년도모음!$E$343:$E$1024,"콘크리트") | S13: =COUNTIFS(과년도모음!$B$343:$B$1024,S$2,과년도모음!$E$343:$E$1024,"콘크리트") | T13: =COUNTIFS(과년도모음!$B$343:$B$1024,T$2,과년도모음!$E$343:$E$1024,"콘크리트") | U13: =COUNTIFS(과년도모음!$B$343:$B$1024,U$2,과년도모음!$E$343:$E$1024,"콘크리트") | V13: =COUNTIFS(과년도모음!$B$343:$B$1024,V$2,과년도모음!$E$343:$E$1024,"콘크리트") | W13: =COUNTIFS(과년도모음!$B$343:$B$1024,W$2,과년도모음!$E$343:$E$1024,"콘크리트") | ... AK13: =COUNTIFS(과년도모음!$B$343:$B$1024,AK$2,과년도모음!$E$343:$E$1024,"콘크리트")
A14: 12 | B14: 토공 | C14: =SUM(E14:AK14) | F14: =COUNTIFS(과년도모음!$B$1:$B$1024,F$2,과년도모음!$E$1:$E$1024,"토공") | G14: =COUNTIFS(과년도모음!$B$1:$B$1024,G$2,과년도모음!$E$1:$E$1024,"토공") | H14: =COUNTIFS(과년도모음!$B$1:$B$1024,H$2,과년도모음!$E$1:$E$1024,"토공") | I14: =COUNTIFS(과년도모음!$B$1:$B$1024,I$2,과년도모음!$E$1:$E$1024,"토공") | J14: =COUNTIFS(과년도모음!$B$1:$B$1024,J$2,과년도모음!$E$1:$E$1024,"토공") | K14: =COUNTIFS(과년도모음!$B$1:$B$1024,K$2,과년도모음!$E$1:$E$1024,"토공") | L14: =COUNTIFS(과년도모음!$B$1:$B$1024,L$2,과년도모음!$E$1:$E$1024,"토공") | M14: =COUNTIFS(과년도모음!$B$1:$B$1024,M$2,과년도모음!$E$1:$E$1024,"토공") | N14: =COUNTIFS(과년도모음!$B$281:$B$1024,N$2,과년도모음!$E$281:$E$1024,"토공") | O14: =COUNTIFS(과년도모음!$B$312:$B$1024,O$2,과년도모음!$E$312:$E$1024,"토공") | P14: =COUNTIFS(과년도모음!$B$343:$B$1024,P$2,과년도모음!$E$343:$E$1024,"토공") | Q14: =COUNTIFS(과년도모음!$B$343:$B$1024,Q$2,과년도모음!$E$343:$E$1024,"토공") | R14: =COUNTIFS(과년도모음!$B$343:$B$1024,R$2,과년도모음!$E$343:$E$1024,"토공") | S14: =COUNTIFS(과년도모음!$B$343:$B$1024,S$2,과년도모음!$E$343:$E$1024,"토공") | T14: =COUNTIFS(과년도모음!$B$343:$B$1024,T$2,과년도모음!$E$343:$E$1024,"토공") | U14: =COUNTIFS(과년도모음!$B$343:$B$1024,U$2,과년도모음!$E$343:$E$1024,"토공") | V14: =COUNTIFS(과년도모음!$B$343:$B$1024,V$2,과년도모음!$E$343:$E$1024,"토공") | W14: =COUNTIFS(과년도모음!$B$343:$B$1024,W$2,과년도모음!$E$343:$E$1024,"토공") | ... AK14: =COUNTIFS(과년도모음!$B$343:$B$1024,AK$2,과년도모음!$E$343:$E$1024,"토공")
A15: 13 | B15: 기초 | C15: =SUM(E15:AK15) | F15: =COUNTIFS(과년도모음!$B$1:$B$1024,F$2,과년도모음!$E$1:$E$1024,"기초") | G15: =COUNTIFS(과년도모음!$B$1:$B$1024,G$2,과년도모음!$E$1:$E$1024,"기초") | H15: =COUNTIFS(과년도모음!$B$1:$B$1024,H$2,과년도모음!$E$1:$E$1024,"기초") | I15: =COUNTIFS(과년도모음!$B$1:$B$1024,I$2,과년도모음!$E$1:$E$1024,"기초") | J15: =COUNTIFS(과년도모음!$B$1:$B$1024,J$2,과년도모음!$E$1:$E$1024,"기초") | K15: =COUNTIFS(과년도모음!$B$1:$B$1024,K$2,과년도모음!$E$1:$E$1024,"기초") | L15: =COUNTIFS(과년도모음!$B$1:$B$1024,L$2,과년도모음!$E$1:$E$1024,"기초") | M15: =COUNTIFS(과년도모음!$B$1:$B$1024,M$2,과년도모음!$E$1:$E$1024,"기초") | N15: =COUNTIFS(과년도모음!$B$281:$B$1024,N$2,과년도모음!$E$281:$E$1024,"기초") | O15: =COUNTIFS(과년도모음!$B$312:$B$1024,O$2,과년도모음!$E$312:$E$1024,"기초") | P15: =COUNTIFS(과년도모음!$B$343:$B$1024,P$2,과년도모음!$E$343:$E$1024,"기초") | Q15: =COUNTIFS(과년도모음!$B$343:$B$1024,Q$2,과년도모음!$E$343:$E$1024,"기초") | R15: =COUNTIFS(과년도모음!$B$343:$B$1024,R$2,과년도모음!$E$343:$E$1024,"기초") | S15: =COUNTIFS(과년도모음!$B$343:$B$1024,S$2,과년도모음!$E$343:$E$1024,"기초") | T15: =COUNTIFS(과년도모음!$B$343:$B$1024,T$2,과년도모음!$E$343:$E$1024,"기초") | U15: =COUNTIFS(과년도모음!$B$343:$B$1024,U$2,과년도모음!$E$343:$E$1024,"기초") | V15: =COUNTIFS(과년도모음!$B$343:$B$1024,V$2,과년도모음!$E$343:$E$1024,"기초") | W15: =COUNTIFS(과년도모음!$B$343:$B$1024,W$2,과년도모음!$E$343:$E$1024,"기초") | ... AK15: =COUNTIFS(과년도모음!$B$343:$B$1024,AK$2,과년도모음!$E$343:$E$1024,"기초")
A16: 14 | B16: 강재 및 철골 | C16: =SUM(E16:AK16) | F16: =COUNTIFS(과년도모음!$B$1:$B$1024,F$2,과년도모음!$E$1:$E$1024,"강재")+COUNTIFS(과년도모음!$B$1:$B$1024,F2,과년도모음!$E$1:$E$1024,"철골") | G16: =COUNTIFS(과년도모음!$B$1:$B$1024,G$2,과년도모음!$E$1:$E$1024,"강재")+COUNTIFS(과년도모음!$B$1:$B$1024,G2,과년도모음!$E$1:$E$1024,"철골") | H16: =COUNTIFS(과년도모음!$B$1:$B$1024,H$2,과년도모음!$E$1:$E$1024,"강재")+COUNTIFS(과년도모음!$B$1:$B$1024,H2,과년도모음!$E$1:$E$1024,"철골") | I16: =COUNTIFS(과년도모음!$B$1:$B$1024,I$2,과년도모음!$E$1:$E$1024,"강재")+COUNTIFS(과년도모음!$B$1:$B$1024,I2,과년도모음!$E$1:$E$1024,"철골") | J16: =COUNTIFS(과년도모음!$B$1:$B$1024,J$2,과년도모음!$E$1:$E$1024,"강재")+COUNTIFS(과년도모음!$B$1:$B$1024,J2,과년도모음!$E$1:$E$1024,"철골") | K16: =COUNTIFS(과년도모음!$B$1:$B$1024,K$2,과년도모음!$E$1:$E$1024,"강재")+COUNTIFS(과년도모음!$B$1:$B$1024,K2,과년도모음!$E$1:$E$1024,"철골") | L16: =COUNTIFS(과년도모음!$B$1:$B$1024,L$2,과년도모음!$E$1:$E$1024,"강재")+COUNTIFS(과년도모음!$B$1:$B$1024,#REF!,과년도모음!$E$1:$E$1024,"철골") | M16: =COUNTIFS(과년도모음!$B$1:$B$1024,M$2,과년도모음!$E$1:$E$1024,"강재")+COUNTIFS(과년도모음!$B$1:$B$1024,#REF!,과년도모음!$E$1:$E$1024,"철골") | N16: =COUNTIFS(과년도모음!$B$281:$B$1024,N$2,과년도모음!$E$281:$E$1024,"강재")+COUNTIFS(과년도모음!$B$281:$B$1024,#REF!,과년도모음!$E$281:$E$1024,"철골") | O16: =COUNTIFS(과년도모음!$B$312:$B$1024,O$2,과년도모음!$E$312:$E$1024,"강재")+COUNTIFS(과년도모음!$B$312:$B$1024,#REF!,과년도모음!$E$312:$E$1024,"철골") | P16: =COUNTIFS(과년도모음!$B$343:$B$1024,P$2,과년도모음!$E$343:$E$1024,"강재")+COUNTIFS(과년도모음!$B$343:$B$1024,#REF!,과년도모음!$E$343:$E$1024,"철골") | Q16: =COUNTIFS(과년도모음!$B$343:$B$1024,Q$2,과년도모음!$E$343:$E$1024,"강재")+COUNTIFS(과년도모음!$B$343:$B$1024,#REF!,과년도모음!$E$343:$E$1024,"철골") | R16: =COUNTIFS(과년도모음!$B$343:$B$1024,R$2,과년도모음!$E$343:$E$1024,"강재")+COUNTIFS(과년도모음!$B$343:$B$1024,#REF!,과년도모음!$E$343:$E$1024,"철골") | S16: =COUNTIFS(과년도모음!$B$343:$B$1024,S$2,과년도모음!$E$343:$E$1024,"강재")+COUNTIFS(과년도모음!$B$343:$B$1024,S$2,과년도모음!$E$343:$E$1024,"철골") | T16: =COUNTIFS(과년도모음!$B$343:$B$1024,T$2,과년도모음!$E$343:$E$1024,"강재")+COUNTIFS(과년도모음!$B$343:$B$1024,T$2,과년도모음!$E$343:$E$1024,"철골") | U16: =COUNTIFS(과년도모음!$B$343:$B$1024,U$2,과년도모음!$E$343:$E$1024,"강재")+COUNTIFS(과년도모음!$B$343:$B$1024,U$2,과년도모음!$E$343:$E$1024,"철골") | V16: =COUNTIFS(과년도모음!$B$343:$B$1024,V$2,과년도모음!$E$343:$E$1024,"강재")+COUNTIFS(과년도모음!$B$343:$B$1024,V$2,과년도모음!$E$343:$E$1024,"철골") | W16: =COUNTIFS(과년도모음!$B$343:$B$1024,W$2,과년도모음!$E$343:$E$1024,"강재")+COUNTIFS(과년도모음!$B$343:$B$1024,W$2,과년도모음!$E$343:$E$1024,"철골") | X16: =COUNTIFS(과년도모음!$B$343:$B$1024,X$2,과년도모음!$E$343:$E$1024,"강재")+COUNTIFS(과년도모음!$B$343:$B$1024,X$2,과년도모음!$E$343:$E$1024,"철골") | Y16: =COUNTIFS(과년도모음!$B$343:$B$1024,Y$2,과년도모음!$E$343:$E$1024,"강재")+COUNTIFS(과년도모음!$B$343:$B$1024,Y$2,과년도모음!$E$343:$E$1024,"철골") | Z16: =COUNTIFS(과년도모음!$B$343:$B$1024,Z$2,과년도모음!$E$343:$E$1024,"강재")+COUNTIFS(과년도모음!$B$343:$B$1024,Z$2,과년도모음!$E$343:$E$1024,"철골") | ... AK16: =COUNTIFS(과년도모음!$B$343:$B$1024,AK$2,과년도모음!$E$343:$E$1024,"강재")+COUNTIFS(과년도모음!$B$343:$B$1024,AK$2,과년도모음!$E$343:$E$1024,"철골")
A17: 15 | B17: 교량 | C17: =SUM(E17:AK17) | F17: =COUNTIFS(과년도모음!$B$1:$B$1024,F$2,과년도모음!$E$1:$E$1024,"교량") | G17: =COUNTIFS(과년도모음!$B$1:$B$1024,G$2,과년도모음!$E$1:$E$1024,"교량") | H17: =COUNTIFS(과년도모음!$B$1:$B$1024,H$2,과년도모음!$E$1:$E$1024,"교량") | I17: =COUNTIFS(과년도모음!$B$1:$B$1024,I$2,과년도모음!$E$1:$E$1024,"교량") | J17: =COUNTIFS(과년도모음!$B$1:$B$1024,J$2,과년도모음!$E$1:$E$1024,"교량") | K17: =COUNTIFS(과년도모음!$B$1:$B$1024,K$2,과년도모음!$E$1:$E$1024,"교량") | L17: =COUNTIFS(과년도모음!$B$1:$B$1024,L$2,과년도모음!$E$1:$E$1024,"교량") | M17: =COUNTIFS(과년도모음!$B$1:$B$1024,M$2,과년도모음!$E$1:$E$1024,"교량") | N17: =COUNTIFS(과년도모음!$B$281:$B$1024,N$2,과년도모음!$E$281:$E$1024,"교량") | O17: =COUNTIFS(과년도모음!$B$312:$B$1024,O$2,과년도모음!$E$312:$E$1024,"교량") | P17: =COUNTIFS(과년도모음!$B$343:$B$1024,P$2,과년도모음!$E$343:$E$1024,"교량") | Q17: =COUNTIFS(과년도모음!$B$343:$B$1024,Q$2,과년도모음!$E$343:$E$1024,"교량") | R17: =COUNTIFS(과년도모음!$B$343:$B$1024,R$2,과년도모음!$E$343:$E$1024,"교량") | S17: =COUNTIFS(과년도모음!$B$343:$B$1024,S$2,과년도모음!$E$343:$E$1024,"교량") | T17: =COUNTIFS(과년도모음!$B$343:$B$1024,T$2,과년도모음!$E$343:$E$1024,"교량") | U17: =COUNTIFS(과년도모음!$B$343:$B$1024,U$2,과년도모음!$E$343:$E$1024,"교량") | V17: =COUNTIFS(과년도모음!$B$343:$B$1024,V$2,과년도모음!$E$343:$E$1024,"교량") | W17: =COUNTIFS(과년도모음!$B$343:$B$1024,W$2,과년도모음!$E$343:$E$1024,"교량") | ... AK17: =COUNTIFS(과년도모음!$B$343:$B$1024,AK$2,과년도모음!$E$343:$E$1024,"교량")
A18: 16 | B18: 터널 | C18: =SUM(E18:AK18) | F18: =COUNTIFS(과년도모음!$B$1:$B$1024,F$2,과년도모음!$E$1:$E$1024,"터널") | G18: =COUNTIFS(과년도모음!$B$1:$B$1024,G$2,과년도모음!$E$1:$E$1024,"터널") | H18: =COUNTIFS(과년도모음!$B$1:$B$1024,H$2,과년도모음!$E$1:$E$1024,"터널") | I18: =COUNTIFS(과년도모음!$B$1:$B$1024,I$2,과년도모음!$E$1:$E$1024,"터널") | J18: =COUNTIFS(과년도모음!$B$1:$B$1024,J$2,과년도모음!$E$1:$E$1024,"터널") | K18: =COUNTIFS(과년도모음!$B$1:$B$1024,K$2,과년도모음!$E$1:$E$1024,"터널") | L18: =COUNTIFS(과년도모음!$B$1:$B$1024,L$2,과년도모음!$E$1:$E$1024,"터널") | M18: =COUNTIFS(과년도모음!$B$1:$B$1024,M$2,과년도모음!$E$1:$E$1024,"터널") | N18: =COUNTIFS(과년도모음!$B$281:$B$1024,N$2,과년도모음!$E$281:$E$1024,"터널") | O18: =COUNTIFS(과년도모음!$B$312:$B$1024,O$2,과년도모음!$E$312:$E$1024,"터널") | P18: =COUNTIFS(과년도모음!$B$343:$B$1024,P$2,과년도모음!$E$343:$E$1024,"터널") | Q18: =COUNTIFS(과년도모음!$B$343:$B$1024,Q$2,과년도모음!$E$343:$E$1024,"터널") | R18: =COUNTIFS(과년도모음!$B$343:$B$1024,R$2,과년도모음!$E$343:$E$1024,"터널") | S18: =COUNTIFS(과년도모음!$B$343:$B$1024,S$2,과년도모음!$E$343:$E$1024,"터널") | T18: =COUNTIFS(과년도모음!$B$343:$B$1024,T$2,과년도모음!$E$343:$E$1024,"터널") | U18: =COUNTIFS(과년도모음!$B$343:$B$1024,U$2,과년도모음!$E$343:$E$1024,"터널") | V18: =COUNTIFS(과년도모음!$B$343:$B$1024,V$2,과년도모음!$E$343:$E$1024,"터널") | W18: =COUNTIFS(과년도모음!$B$343:$B$1024,W$2,과년도모음!$E$343:$E$1024,"터널") | ... AK18: =COUNTIFS(과년도모음!$B$343:$B$1024,AK$2,과년도모음!$E$343:$E$1024,"터널")
A19: 17 | B19: 건축 | C19: =SUM(E19:AK19) | F19: =COUNTIFS(과년도모음!$B$1:$B$1024,F$2,과년도모음!$E$1:$E$1024,"건축") | G19: =COUNTIFS(과년도모음!$B$1:$B$1024,G$2,과년도모음!$E$1:$E$1024,"건축") | H19: =COUNTIFS(과년도모음!$B$1:$B$1024,H$2,과년도모음!$E$1:$E$1024,"건축") | I19: =COUNTIFS(과년도모음!$B$1:$B$1024,I$2,과년도모음!$E$1:$E$1024,"건축") | J19: =COUNTIFS(과년도모음!$B$1:$B$1024,J$2,과년도모음!$E$1:$E$1024,"건축") | K19: =COUNTIFS(과년도모음!$B$1:$B$1024,K$2,과년도모음!$E$1:$E$1024,"건축") | L19: =COUNTIFS(과년도모음!$B$1:$B$1024,L$2,과년도모음!$E$1:$E$1024,"건축") | M19: =COUNTIFS(과년도모음!$B$1:$B$1024,M$2,과년도모음!$E$1:$E$1024,"건축") | N19: =COUNTIFS(과년도모음!$B$281:$B$1024,N$2,과년도모음!$E$281:$E$1024,"건축") | O19: =COUNTIFS(과년도모음!$B$312:$B$1024,O$2,과년도모음!$E$312:$E$1024,"건축") | P19: =COUNTIFS(과년도모음!$B$343:$B$1024,P$2,과년도모음!$E$343:$E$1024,"건축") | Q19: =COUNTIFS(과년도모음!$B$343:$B$1024,Q$2,과년도모음!$E$343:$E$1024,"건축") | R19: =COUNTIFS(과년도모음!$B$343:$B$1024,R$2,과년도모음!$E$343:$E$1024,"건축") | S19: =COUNTIFS(과년도모음!$B$343:$B$1024,S$2,과년도모음!$E$343:$E$1024,"건축") | T19: =COUNTIFS(과년도모음!$B$343:$B$1024,T$2,과년도모음!$E$343:$E$1024,"건축") | U19: =COUNTIFS(과년도모음!$B$343:$B$1024,U$2,과년도모음!$E$343:$E$1024,"건축") | V19: =COUNTIFS(과년도모음!$B$343:$B$1024,V$2,과년도모음!$E$343:$E$1024,"건축") | W19: =COUNTIFS(과년도모음!$B$343:$B$1024,W$2,과년도모음!$E$343:$E$1024,"건축") | ... AK19: =COUNTIFS(과년도모음!$B$343:$B$1024,AK$2,과년도모음!$E$343:$E$1024,"건축")
A20: 18 | B20: 지진 | C20: =SUM(E20:AK20) | F20: =COUNTIFS(과년도모음!$B$1:$B$1024,F$2,과년도모음!$E$1:$E$1024,"지진") | G20: =COUNTIFS(과년도모음!$B$1:$B$1024,G$2,과년도모음!$E$1:$E$1024,"지진") | H20: =COUNTIFS(과년도모음!$B$1:$B$1024,H$2,과년도모음!$E$1:$E$1024,"지진") | I20: =COUNTIFS(과년도모음!$B$1:$B$1024,I$2,과년도모음!$E$1:$E$1024,"지진") | J20: =COUNTIFS(과년도모음!$B$1:$B$1024,J$2,과년도모음!$E$1:$E$1024,"지진") | K20: =COUNTIFS(과년도모음!$B$1:$B$1024,K$2,과년도모음!$E$1:$E$1024,"지진") | L20: =COUNTIFS(과년도모음!$B$1:$B$1024,L$2,과년도모음!$E$1:$E$1024,"지진") | M20: =COUNTIFS(과년도모음!$B$1:$B$1024,M$2,과년도모음!$E$1:$E$1024,"지진") | N20: =COUNTIFS(과년도모음!$B$281:$B$1024,N$2,과년도모음!$E$281:$E$1024,"지진") | O20: =COUNTIFS(과년도모음!$B$312:$B$1024,O$2,과년도모음!$E$312:$E$1024,"지진") | P20: =COUNTIFS(과년도모음!$B$343:$B$1024,P$2,과년도모음!$E$343:$E$1024,"지진") | Q20: =COUNTIFS(과년도모음!$B$343:$B$1024,Q$2,과년도모음!$E$343:$E$1024,"지진") | R20: =COUNTIFS(과년도모음!$B$343:$B$1024,R$2,과년도모음!$E$343:$E$1024,"지진") | S20: =COUNTIFS(과년도모음!$B$343:$B$1024,S$2,과년도모음!$E$343:$E$1024,"지진") | T20: =COUNTIFS(과년도모음!$B$343:$B$1024,T$2,과년도모음!$E$343:$E$1024,"지진") | U20: =COUNTIFS(과년도모음!$B$343:$B$1024,U$2,과년도모음!$E$343:$E$1024,"지진") | V20: =COUNTIFS(과년도모음!$B$343:$B$1024,V$2,과년도모음!$E$343:$E$1024,"지진") | W20: =COUNTIFS(과년도모음!$B$343:$B$1024,W$2,과년도모음!$E$343:$E$1024,"지진") | ... AK20: =COUNTIFS(과년도모음!$B$343:$B$1024,AK$2,과년도모음!$E$343:$E$1024,"지진")
A21: 19 | B21: 해체공사 | C21: =SUM(E21:AK21) | F21: =COUNTIFS(과년도모음!$B$1:$B$1024,F$2,과년도모음!$E$1:$E$1024,"해체공사") | G21: =COUNTIFS(과년도모음!$B$1:$B$1024,G$2,과년도모음!$E$1:$E$1024,"해체공사") | H21: =COUNTIFS(과년도모음!$B$1:$B$1024,H$2,과년도모음!$E$1:$E$1024,"해체공사") | I21: =COUNTIFS(과년도모음!$B$1:$B$1024,I$2,과년도모음!$E$1:$E$1024,"해체공사") | J21: =COUNTIFS(과년도모음!$B$1:$B$1024,J$2,과년도모음!$E$1:$E$1024,"해체공사") | K21: =COUNTIFS(과년도모음!$B$1:$B$1024,K$2,과년도모음!$E$1:$E$1024,"해체공사") | L21: =COUNTIFS(과년도모음!$B$1:$B$1024,L$2,과년도모음!$E$1:$E$1024,"해체공사") | M21: =COUNTIFS(과년도모음!$B$1:$B$1024,M$2,과년도모음!$E$1:$E$1024,"해체공사") | N21: =COUNTIFS(과년도모음!$B$281:$B$1024,N$2,과년도모음!$E$281:$E$1024,"해체공사") | O21: =COUNTIFS(과년도모음!$B$312:$B$1024,O$2,과년도모음!$E$312:$E$1024,"해체공사") | P21: =COUNTIFS(과년도모음!$B$343:$B$1024,P$2,과년도모음!$E$343:$E$1024,"해체공사") | Q21: =COUNTIFS(과년도모음!$B$343:$B$1024,Q$2,과년도모음!$E$343:$E$1024,"해체공사") | R21: =COUNTIFS(과년도모음!$B$343:$B$1024,R$2,과년도모음!$E$343:$E$1024,"해체공사") | S21: =COUNTIFS(과년도모음!$B$343:$B$1024,S$2,과년도모음!$E$343:$E$1024,"해체공사") | T21: =COUNTIFS(과년도모음!$B$343:$B$1024,T$2,과년도모음!$E$343:$E$1024,"해체공사") | U21: =COUNTIFS(과년도모음!$B$343:$B$1024,U$2,과년도모음!$E$343:$E$1024,"해체공사") | V21: =COUNTIFS(과년도모음!$B$343:$B$1024,V$2,과년도모음!$E$343:$E$1024,"해체공사") | W21: =COUNTIFS(과년도모음!$B$343:$B$1024,W$2,과년도모음!$E$343:$E$1024,"해체공사") | ... AK21: =COUNTIFS(과년도모음!$B$343:$B$1024,AK$2,과년도모음!$E$343:$E$1024,"해체공사")
A22: 20 | B22: 시사이슈 | C22: =SUM(E22:AK22) | F22: =COUNTIFS(과년도모음!$B$1:$B$1024,F$2,과년도모음!$E$1:$E$1024,"시사 이슈 문제") | G22: =COUNTIFS(과년도모음!$B$1:$B$1024,G$2,과년도모음!$E$1:$E$1024,"시사 이슈 문제") | H22: =COUNTIFS(과년도모음!$B$1:$B$1024,H$2,과년도모음!$E$1:$E$1024,"시사 이슈 문제") | I22: =COUNTIFS(과년도모음!$B$1:$B$1024,I$2,과년도모음!$E$1:$E$1024,"시사 이슈 문제") | J22: =COUNTIFS(과년도모음!$B$1:$B$1024,J$2,과년도모음!$E$1:$E$1024,"시사 이슈 문제") | K22: =COUNTIFS(과년도모음!$B$1:$B$1024,K$2,과년도모음!$E$1:$E$1024,"시사 이슈 문제") | L22: =COUNTIFS(과년도모음!$B$1:$B$1024,L$2,과년도모음!$E$1:$E$1024,"시사 이슈 문제") | M22: =COUNTIFS(과년도모음!$B$1:$B$1024,M$2,과년도모음!$E$1:$E$1024,"시사 이슈 문제") | N22: =COUNTIFS(과년도모음!$B$281:$B$1024,N$2,과년도모음!$E$281:$E$1024,"시사 이슈 문제") | O22: =COUNTIFS(과년도모음!$B$312:$B$1024,O$2,과년도모음!$E$312:$E$1024,"시사 이슈 문제") | P22: =COUNTIFS(과년도모음!$B$343:$B$1024,P$2,과년도모음!$E$343:$E$1024,"시사 이슈 문제") | Q22: =COUNTIFS(과년도모음!$B$343:$B$1024,Q$2,과년도모음!$E$343:$E$1024,"시사 이슈 문제") | R22: =COUNTIFS(과년도모음!$B$343:$B$1024,R$2,과년도모음!$E$343:$E$1024,"시사 이슈 문제") | S22: =COUNTIFS(과년도모음!$B$343:$B$1024,S$2,과년도모음!$E$343:$E$1024,"시사 이슈 문제") | T22: =COUNTIFS(과년도모음!$B$343:$B$1024,T$2,과년도모음!$E$343:$E$1024,"시사 이슈 문제") | U22: =COUNTIFS(과년도모음!$B$343:$B$1024,U$2,과년도모음!$E$343:$E$1024,"시사 이슈 문제") | V22: =COUNTIFS(과년도모음!$B$343:$B$1024,V$2,과년도모음!$E$343:$E$1024,"시사 이슈 문제") | W22: =COUNTIFS(과년도모음!$B$343:$B$1024,W$2,과년도모음!$E$343:$E$1024,"시사 이슈 문제") | ... AK22: =COUNTIFS(과년도모음!$B$343:$B$1024,AK$2,과년도모음!$E$343:$E$1024,"시사 이슈 문제")
A23: 21 | B23: 기타(댐 제방 항만) | C23: =SUM(E23:AK23) | F23: =COUNTIFS(과년도모음!$B$1:$B$1024,F$2,과년도모음!$E$1:$E$1024,"제방 댐 항만")+COUNTIFS(과년도모음!$B$1:$B$1024,F$27,과년도모음!$E$1:$E$1024,"기타") | G23: =COUNTIFS(과년도모음!$B$1:$B$1024,G$2,과년도모음!$E$1:$E$1024,"제방 댐 항만")+COUNTIFS(과년도모음!$B$1:$B$1024,G$27,과년도모음!$E$1:$E$1024,"기타") | H23: =COUNTIFS(과년도모음!$B$1:$B$1024,H$2,과년도모음!$E$1:$E$1024,"제방 댐 항만")+COUNTIFS(과년도모음!$B$1:$B$1024,H$27,과년도모음!$E$1:$E$1024,"기타") | I23: =COUNTIFS(과년도모음!$B$1:$B$1024,I$2,과년도모음!$E$1:$E$1024,"제방 댐 항만")+COUNTIFS(과년도모음!$B$1:$B$1024,I$27,과년도모음!$E$1:$E$1024,"기타") | J23: =COUNTIFS(과년도모음!$B$1:$B$1024,J$2,과년도모음!$E$1:$E$1024,"제방 댐 항만")+COUNTIFS(과년도모음!$B$1:$B$1024,J$27,과년도모음!$E$1:$E$1024,"기타") | K23: =COUNTIFS(과년도모음!$B$1:$B$1024,K$2,과년도모음!$E$1:$E$1024,"제방 댐 항만")+COUNTIFS(과년도모음!$B$1:$B$1024,K$27,과년도모음!$E$1:$E$1024,"기타") | L23: =COUNTIFS(과년도모음!$B$1:$B$1024,L$2,과년도모음!$E$1:$E$1024,"제방 댐 항만")+COUNTIFS(과년도모음!$B$1:$B$1024,L$27,과년도모음!$E$1:$E$1024,"기타") | M23: =COUNTIFS(과년도모음!$B$1:$B$1024,M$2,과년도모음!$E$1:$E$1024,"제방 댐 항만")+COUNTIFS(과년도모음!$B$1:$B$1024,M$27,과년도모음!$E$1:$E$1024,"기타") | N23: =COUNTIFS(과년도모음!$B$281:$B$1024,N$2,과년도모음!$E$281:$E$1024,"제방 댐 항만")+COUNTIFS(과년도모음!$B$281:$B$1024,N$27,과년도모음!$E$281:$E$1024,"기타") | O23: =COUNTIFS(과년도모음!$B$312:$B$1024,O$2,과년도모음!$E$312:$E$1024,"제방 댐 항만")+COUNTIFS(과년도모음!$B$312:$B$1024,O$27,과년도모음!$E$312:$E$1024,"기타") | P23: =COUNTIFS(과년도모음!$B$343:$B$1024,P$2,과년도모음!$E$343:$E$1024,"제방 댐 항만")+COUNTIFS(과년도모음!$B$343:$B$1024,P$27,과년도모음!$E$343:$E$1024,"기타") | Q23: =COUNTIFS(과년도모음!$B$343:$B$1024,Q$2,과년도모음!$E$343:$E$1024,"제방 댐 항만")+COUNTIFS(과년도모음!$B$343:$B$1024,#REF!,과년도모음!$E$343:$E$1024,"기타") | R23: =COUNTIFS(과년도모음!$B$343:$B$1024,R$2,과년도모음!$E$343:$E$1024,"제방 댐 항만")+COUNTIFS(과년도모음!$B$343:$B$1024,#REF!,과년도모음!$E$343:$E$1024,"기타") | S23: =COUNTIFS(과년도모음!$B$343:$B$1024,S$2,과년도모음!$E$343:$E$1024,"제방 댐 항만")+COUNTIFS(과년도모음!$B$343:$B$1024,#REF!,과년도모음!$E$343:$E$1024,"기타") | T23: =COUNTIFS(과년도모음!$B$343:$B$1024,T$2,과년도모음!$E$343:$E$1024,"제방 댐 항만")+COUNTIFS(과년도모음!$B$343:$B$1024,#REF!,과년도모음!$E$343:$E$1024,"기타") | U23: =COUNTIFS(과년도모음!$B$343:$B$1024,U$2,과년도모음!$E$343:$E$1024,"제방 댐 항만")+COUNTIFS(과년도모음!$B$343:$B$1024,#REF!,과년도모음!$E$343:$E$1024,"기타") | V23: =COUNTIFS(과년도모음!$B$343:$B$1024,V$2,과년도모음!$E$343:$E$1024,"제방 댐 항만")+COUNTIFS(과년도모음!$B$343:$B$1024,#REF!,과년도모음!$E$343:$E$1024,"기타") | W23: =COUNTIFS(과년도모음!$B$343:$B$1024,W$2,과년도모음!$E$343:$E$1024,"제방 댐 항만")+COUNTIFS(과년도모음!$B$343:$B$1024,#REF!,과년도모음!$E$343:$E$1024,"기타") | X23: =COUNTIFS(과년도모음!$B$343:$B$1024,X$2,과년도모음!$E$343:$E$1024,"제방 댐 항만")+COUNTIFS(과년도모음!$B$343:$B$1024,X$2,과년도모음!$E$343:$E$1024,"기타") | Y23: =COUNTIFS(과년도모음!$B$343:$B$1024,Y$2,과년도모음!$E$343:$E$1024,"제방 댐 항만")+COUNTIFS(과년도모음!$B$343:$B$1024,Y$2,과년도모음!$E$343:$E$1024,"기타") | Z23: =COUNTIFS(과년도모음!$B$343:$B$1024,Z$2,과년도모음!$E$343:$E$1024,"제방 댐 항만")+COUNTIFS(과년도모음!$B$343:$B$1024,Z$2,과년도모음!$E$343:$E$1024,"기타") | AA23: =COUNTIFS(과년도모음!$B$343:$B$1024,AA$2,과년도모음!$E$343:$E$1024,"제방 댐 항만")+COUNTIFS(과년도모음!$B$343:$B$1024,AA$2,과년도모음!$E$343:$E$1024,"기타") | AB23: =COUNTIFS(과년도모음!$B$343:$B$1024,AB$2,과년도모음!$E$343:$E$1024,"제방 댐 항만")+COUNTIFS(과년도모음!$B$343:$B$1024,AB$2,과년도모음!$E$343:$E$1024,"기타") | AC23: =COUNTIFS(과년도모음!$B$343:$B$1024,AC$2,과년도모음!$E$343:$E$1024,"제방 댐 항만")+COUNTIFS(과년도모음!$B$343:$B$1024,AC$2,과년도모음!$E$343:$E$1024,"기타") | AD23: =COUNTIFS(과년도모음!$B$343:$B$1024,AD$2,과년도모음!$E$343:$E$1024,"제방 댐 항만")+COUNTIFS(과년도모음!$B$343:$B$1024,AD$2,과년도모음!$E$343:$E$1024,"기타") | AE23: =COUNTIFS(과년도모음!$B$343:$B$1024,AE$2,과년도모음!$E$343:$E$1024,"제방 댐 항만")+COUNTIFS(과년도모음!$B$343:$B$1024,AE$2,과년도모음!$E$343:$E$1024,"기타") | ... AK23: =COUNTIFS(과년도모음!$B$343:$B$1024,AK$2,과년도모음!$E$343:$E$1024,"제방 댐 항만")+COUNTIFS(과년도모음!$B$343:$B$1024,AK$2,과년도모음!$E$343:$E$1024,"기타")
B24: 합계 | C24: =SUM(C3:C23) | F24: =SUM(F3:F23) | G24: =SUM(G3:G23) | H24: =SUM(H3:H23) | I24: =SUM(I3:I23) | J24: =SUM(J3:J23) | K24: =SUM(K3:K23) | L24: =SUM(L3:L23) | M24: =SUM(M3:M23) | ... AK24: =SUM(AK3:AK23)
A26: □ 건설안전기술사 과년도 출제빈도 順 분석(106회~137회)
A27: RANK | B27: 분류 | C27: 출제확율 | D27: 평균 | E27: 합계 | F27: 137 | G27: 136 | H27: 135회 | I27: 134 | J27: 133 | K27: 132 | L27: 131 | M27: 130 | N27: 129 | O27: 128 | P27: 127 | Q27: 126 | R27: 125 | S27: 124 | T27: 123 | U27: 122 | V27: 121 | W27: 120 | X27: 119 | Y27: 118 | Z27: 117 | AA27: 116 | AB27: 115 | AC27: 114 | AD27: 113 | AE27: 112 | AF27: 111 | AG27: 110 | AH27: 109 | AI27: 108 | AJ27: 107 | AK27: 106 | AL27: 비고
A28: =RANK(E28,$E$28:$E$48) | B28: 산업안전보건법 | C28: =E28/$E$49 | D28: =E28/22 | E28: =SUM(F28:AK28) | F28: =COUNTIFS(과년도모음!$B$1:$B$1024,F$2,과년도모음!$E$1:$E$1024,"산안법") | G28: =COUNTIFS(과년도모음!$B$1:$B$1024,G$2,과년도모음!$E$1:$E$1024,"산안법") | H28: =COUNTIFS(과년도모음!$B$1:$B$1024,H$2,과년도모음!$E$1:$E$1024,"산안법") | I28: =COUNTIFS(과년도모음!$B$1:$B$1024,I$2,과년도모음!$E$1:$E$1024,"산안법") | J28: =COUNTIFS(과년도모음!$B$1:$B$1024,J$2,과년도모음!$E$1:$E$1024,"산안법") | K28: =COUNTIFS(과년도모음!$B$1:$B$1024,K$2,과년도모음!$E$1:$E$1024,"산안법") | L28: =COUNTIFS(과년도모음!$B$1:$B$1024,L$2,과년도모음!$E$1:$E$1024,"산안법") | M28: =COUNTIFS(과년도모음!$B$1:$B$1024,M$2,과년도모음!$E$1:$E$1024,"산안법") | N28: =COUNTIFS(과년도모음!$B$281:$B$1024,N$2,과년도모음!$E$281:$E$1024,"산안법") | O28: =COUNTIFS(과년도모음!$B$312:$B$1024,O$2,과년도모음!$E$312:$E$1024,"산안법") | P28: =COUNTIFS(과년도모음!$B$343:$B$1024,P$2,과년도모음!$E$343:$E$1024,"산안법") | Q28: =COUNTIFS(과년도모음!$B$343:$B$1024,Q$2,과년도모음!$E$343:$E$1024,"산안법") | R28: =COUNTIFS(과년도모음!$B$405:$B$1024,R$2,과년도모음!$E$405:$E$1024,"산안법") | S28: =COUNTIFS(과년도모음!$B$405:$B$1024,S$2,과년도모음!$E$405:$E$1024,"산안법") | T28: =COUNTIFS(과년도모음!$B$405:$B$1024,T$2,과년도모음!$E$405:$E$1024,"산안법") | U28: =COUNTIFS(과년도모음!$B$405:$B$1024,U$2,과년도모음!$E$405:$E$1024,"산안법") | V28: =COUNTIFS(과년도모음!$B$405:$B$1024,V$2,과년도모음!$E$405:$E$1024,"산안법") | W28: =COUNTIFS(과년도모음!$B$405:$B$1024,W$2,과년도모음!$E$405:$E$1024,"산안법") | X28: =COUNTIFS(과년도모음!$B$405:$B$1024,X$2,과년도모음!$E$405:$E$1024,"산안법") | Y28: =COUNTIFS(과년도모음!$B$405:$B$1024,Y$2,과년도모음!$E$405:$E$1024,"산안법") | ... AK28: =COUNTIFS(과년도모음!$B$405:$B$1024,AK$2,과년도모음!$E$405:$E$1024,"산안법")
A29: =RANK(E29,$E$28:$E$48) | B29: 안전관리론 | C29: =E29/$E$49 | D29: =E29/22 | E29: =SUM(F29:AK29) | F29: =COUNTIFS(과년도모음!$B$1:$B$1024,F$2,과년도모음!$E$1:$E$1024,"안전관리론") | G29: =COUNTIFS(과년도모음!$B$1:$B$1024,G$2,과년도모음!$E$1:$E$1024,"안전관리론") | H29: =COUNTIFS(과년도모음!$B$1:$B$1024,H$2,과년도모음!$E$1:$E$1024,"안전관리론") | I29: =COUNTIFS(과년도모음!$B$1:$B$1024,I$2,과년도모음!$E$1:$E$1024,"안전관리론") | J29: =COUNTIFS(과년도모음!$B$1:$B$1024,J$2,과년도모음!$E$1:$E$1024,"안전관리론") | K29: =COUNTIFS(과년도모음!$B$1:$B$1024,K$2,과년도모음!$E$1:$E$1024,"안전관리론") | L29: =COUNTIFS(과년도모음!$B$1:$B$1024,L$2,과년도모음!$E$1:$E$1024,"안전관리론") | M29: =COUNTIFS(과년도모음!$B$1:$B$1024,M$2,과년도모음!$E$1:$E$1024,"안전관리론") | N29: =COUNTIFS(과년도모음!$B$281:$B$1024,N$2,과년도모음!$E$281:$E$1024,"안전관리론") | O29: =COUNTIFS(과년도모음!$B$312:$B$1024,O$2,과년도모음!$E$312:$E$1024,"안전관리론") | P29: =COUNTIFS(과년도모음!$B$343:$B$1024,P$2,과년도모음!$E$343:$E$1024,"안전관리론") | Q29: =COUNTIFS(과년도모음!$B$343:$B$1024,Q$2,과년도모음!$E$343:$E$1024,"안전관리론") | R29: =COUNTIFS(과년도모음!$B$405:$B$1024,R$2,과년도모음!$E$405:$E$1024,"안전관리론") | S29: =COUNTIFS(과년도모음!$B$405:$B$1024,S$2,과년도모음!$E$405:$E$1024,"안전관리론") | T29: =COUNTIFS(과년도모음!$B$405:$B$1024,T$2,과년도모음!$E$405:$E$1024,"안전관리론") | U29: =COUNTIFS(과년도모음!$B$405:$B$1024,U$2,과년도모음!$E$405:$E$1024,"안전관리론") | V29: =COUNTIFS(과년도모음!$B$405:$B$1024,V$2,과년도모음!$E$405:$E$1024,"안전관리론") | W29: =COUNTIFS(과년도모음!$B$405:$B$1024,W$2,과년도모음!$E$405:$E$1024,"안전관리론") | X29: =COUNTIFS(과년도모음!$B$405:$B$1024,X$2,과년도모음!$E$405:$E$1024,"안전관리론") | Y29: =COUNTIFS(과년도모음!$B$405:$B$1024,Y$2,과년도모음!$E$405:$E$1024,"안전관리론") | ... AK29: =COUNTIFS(과년도모음!$B$405:$B$1024,AK$2,과년도모음!$E$405:$E$1024,"안전관리론")
A30: =RANK(E30,$E$28:$E$48) | B30: 콘크리트(거푸집 동바리 철근 포함) | C30: =E30/$E$49 | D30: =E30/22 | E30: =SUM(F30:AK30) | F30: =COUNTIFS(과년도모음!$B$1:$B$1024,F$2,과년도모음!$E$1:$E$1024,"콘크리트") | G30: =COUNTIFS(과년도모음!$B$1:$B$1024,G$2,과년도모음!$E$1:$E$1024,"콘크리트") | H30: =COUNTIFS(과년도모음!$B$1:$B$1024,H$2,과년도모음!$E$1:$E$1024,"콘크리트") | I30: =COUNTIFS(과년도모음!$B$1:$B$1024,I$2,과년도모음!$E$1:$E$1024,"콘크리트") | J30: =COUNTIFS(과년도모음!$B$1:$B$1024,J$2,과년도모음!$E$1:$E$1024,"콘크리트") | K30: =COUNTIFS(과년도모음!$B$1:$B$1024,K$2,과년도모음!$E$1:$E$1024,"콘크리트") | L30: =COUNTIFS(과년도모음!$B$1:$B$1024,L$2,과년도모음!$E$1:$E$1024,"콘크리트") | M30: =COUNTIFS(과년도모음!$B$1:$B$1024,M$2,과년도모음!$E$1:$E$1024,"콘크리트") | N30: =COUNTIFS(과년도모음!$B$281:$B$1024,N$2,과년도모음!$E$281:$E$1024,"콘크리트") | O30: =COUNTIFS(과년도모음!$B$312:$B$1024,O$2,과년도모음!$E$312:$E$1024,"콘크리트") | P30: =COUNTIFS(과년도모음!$B$343:$B$1024,P$2,과년도모음!$E$343:$E$1024,"콘크리트") | Q30: =COUNTIFS(과년도모음!$B$343:$B$1024,Q$2,과년도모음!$E$343:$E$1024,"콘크리트") | R30: =COUNTIFS(과년도모음!$B$405:$B$1024,R$2,과년도모음!$E$405:$E$1024,"콘크리트") | S30: =COUNTIFS(과년도모음!$B$405:$B$1024,S$2,과년도모음!$E$405:$E$1024,"콘크리트") | T30: =COUNTIFS(과년도모음!$B$405:$B$1024,T$2,과년도모음!$E$405:$E$1024,"콘크리트") | U30: =COUNTIFS(과년도모음!$B$405:$B$1024,U$2,과년도모음!$E$405:$E$1024,"콘크리트") | V30: =COUNTIFS(과년도모음!$B$405:$B$1024,V$2,과년도모음!$E$405:$E$1024,"콘크리트") | W30: =COUNTIFS(과년도모음!$B$405:$B$1024,W$2,과년도모음!$E$405:$E$1024,"콘크리트") | X30: =COUNTIFS(과년도모음!$B$405:$B$1024,X$2,과년도모음!$E$405:$E$1024,"콘크리트") | Y30: =COUNTIFS(과년도모음!$B$405:$B$1024,Y$2,과년도모음!$E$405:$E$1024,"콘크리트") | ... AK30: =COUNTIFS(과년도모음!$B$405:$B$1024,AK$2,과년도모음!$E$405:$E$1024,"콘크리트")
A31: =RANK(E31,$E$28:$E$48) | B31: 건설기계 | C31: =E31/$E$49 | D31: =E31/22 | E31: =SUM(F31:AK31) | F31: =COUNTIFS(과년도모음!$B$1:$B$1024,F$2,과년도모음!$E$1:$E$1024,"건설기계") | G31: =COUNTIFS(과년도모음!$B$1:$B$1024,G$2,과년도모음!$E$1:$E$1024,"건설기계") | H31: =COUNTIFS(과년도모음!$B$1:$B$1024,H$2,과년도모음!$E$1:$E$1024,"건설기계") | I31: =COUNTIFS(과년도모음!$B$1:$B$1024,I$2,과년도모음!$E$1:$E$1024,"건설기계") | J31: =COUNTIFS(과년도모음!$B$1:$B$1024,J$2,과년도모음!$E$1:$E$1024,"건설기계") | K31: =COUNTIFS(과년도모음!$B$1:$B$1024,K$2,과년도모음!$E$1:$E$1024,"건설기계") | L31: =COUNTIFS(과년도모음!$B$1:$B$1024,L$2,과년도모음!$E$1:$E$1024,"건설기계") | M31: =COUNTIFS(과년도모음!$B$1:$B$1024,M$2,과년도모음!$E$1:$E$1024,"건설기계") | N31: =COUNTIFS(과년도모음!$B$281:$B$1024,N$2,과년도모음!$E$281:$E$1024,"건설기계") | O31: =COUNTIFS(과년도모음!$B$312:$B$1024,O$2,과년도모음!$E$312:$E$1024,"건설기계") | P31: =COUNTIFS(과년도모음!$B$343:$B$1024,P$2,과년도모음!$E$343:$E$1024,"건설기계") | Q31: =COUNTIFS(과년도모음!$B$343:$B$1024,Q$2,과년도모음!$E$343:$E$1024,"건설기계") | R31: =COUNTIFS(과년도모음!$B$405:$B$1024,R$2,과년도모음!$E$405:$E$1024,"건설기계") | S31: =COUNTIFS(과년도모음!$B$405:$B$1024,S$2,과년도모음!$E$405:$E$1024,"건설기계") | T31: =COUNTIFS(과년도모음!$B$405:$B$1024,T$2,과년도모음!$E$405:$E$1024,"건설기계") | U31: =COUNTIFS(과년도모음!$B$405:$B$1024,U$2,과년도모음!$E$405:$E$1024,"건설기계") | V31: =COUNTIFS(과년도모음!$B$405:$B$1024,V$2,과년도모음!$E$405:$E$1024,"건설기계") | W31: =COUNTIFS(과년도모음!$B$405:$B$1024,W$2,과년도모음!$E$405:$E$1024,"건설기계") | X31: =COUNTIFS(과년도모음!$B$405:$B$1024,X$2,과년도모음!$E$405:$E$1024,"건설기계") | Y31: =COUNTIFS(과년도모음!$B$405:$B$1024,Y$2,과년도모음!$E$405:$E$1024,"건설기계") | ... AK31: =COUNTIFS(과년도모음!$B$405:$B$1024,AK$2,과년도모음!$E$405:$E$1024,"건설기계")
A32: =RANK(E32,$E$28:$E$48) | B32: 가설공사 | C32: =E32/$E$49 | D32: =E32/22 | E32: =SUM(F32:AK32) | F32: =COUNTIFS(과년도모음!$B$1:$B$1024,F$2,과년도모음!$E$1:$E$1024,"가설공사") | G32: =COUNTIFS(과년도모음!$B$1:$B$1024,G$2,과년도모음!$E$1:$E$1024,"가설공사") | H32: =COUNTIFS(과년도모음!$B$1:$B$1024,H$2,과년도모음!$E$1:$E$1024,"가설공사") | I32: =COUNTIFS(과년도모음!$B$1:$B$1024,I$2,과년도모음!$E$1:$E$1024,"가설공사") | J32: =COUNTIFS(과년도모음!$B$1:$B$1024,J$2,과년도모음!$E$1:$E$1024,"가설공사") | K32: =COUNTIFS(과년도모음!$B$1:$B$1024,K$2,과년도모음!$E$1:$E$1024,"가설공사") | L32: =COUNTIFS(과년도모음!$B$1:$B$1024,L$2,과년도모음!$E$1:$E$1024,"가설공사") | M32: =COUNTIFS(과년도모음!$B$1:$B$1024,M$2,과년도모음!$E$1:$E$1024,"가설공사") | N32: =COUNTIFS(과년도모음!$B$281:$B$1024,N$2,과년도모음!$E$281:$E$1024,"가설공사") | O32: =COUNTIFS(과년도모음!$B$312:$B$1024,O$2,과년도모음!$E$312:$E$1024,"가설공사") | P32: =COUNTIFS(과년도모음!$B$343:$B$1024,P$2,과년도모음!$E$343:$E$1024,"가설공사") | Q32: =COUNTIFS(과년도모음!$B$343:$B$1024,Q$2,과년도모음!$E$343:$E$1024,"가설공사") | R32: =COUNTIFS(과년도모음!$B$405:$B$1024,R$2,과년도모음!$E$405:$E$1024,"가설공사") | S32: =COUNTIFS(과년도모음!$B$405:$B$1024,S$2,과년도모음!$E$405:$E$1024,"가설공사") | T32: =COUNTIFS(과년도모음!$B$405:$B$1024,T$2,과년도모음!$E$405:$E$1024,"가설공사") | U32: =COUNTIFS(과년도모음!$B$405:$B$1024,U$2,과년도모음!$E$405:$E$1024,"가설공사") | V32: =COUNTIFS(과년도모음!$B$405:$B$1024,V$2,과년도모음!$E$405:$E$1024,"가설공사") | W32: =COUNTIFS(과년도모음!$B$405:$B$1024,W$2,과년도모음!$E$405:$E$1024,"가설공사") | X32: =COUNTIFS(과년도모음!$B$405:$B$1024,X$2,과년도모음!$E$405:$E$1024,"가설공사") | Y32: =COUNTIFS(과년도모음!$B$405:$B$1024,Y$2,과년도모음!$E$405:$E$1024,"가설공사") | ... AK32: =COUNTIFS(과년도모음!$B$405:$B$1024,AK$2,과년도모음!$E$405:$E$1024,"가설공사")
A33: =RANK(E33,$E$28:$E$48) | B33: 기초 | C33: =E33/$E$49 | D33: =E33/22 | E33: =SUM(F33:AK33) | F33: =COUNTIFS(과년도모음!$B$1:$B$1024,F$2,과년도모음!$E$1:$E$1024,"기초") | G33: =COUNTIFS(과년도모음!$B$1:$B$1024,G$2,과년도모음!$E$1:$E$1024,"기초") | H33: =COUNTIFS(과년도모음!$B$1:$B$1024,H$2,과년도모음!$E$1:$E$1024,"기초") | I33: =COUNTIFS(과년도모음!$B$1:$B$1024,I$2,과년도모음!$E$1:$E$1024,"기초") | J33: =COUNTIFS(과년도모음!$B$1:$B$1024,J$2,과년도모음!$E$1:$E$1024,"기초") | K33: =COUNTIFS(과년도모음!$B$1:$B$1024,K$2,과년도모음!$E$1:$E$1024,"기초") | L33: =COUNTIFS(과년도모음!$B$1:$B$1024,L$2,과년도모음!$E$1:$E$1024,"기초") | M33: =COUNTIFS(과년도모음!$B$1:$B$1024,M$2,과년도모음!$E$1:$E$1024,"기초") | N33: =COUNTIFS(과년도모음!$B$281:$B$1024,N$2,과년도모음!$E$281:$E$1024,"기초") | O33: =COUNTIFS(과년도모음!$B$312:$B$1024,O$2,과년도모음!$E$312:$E$1024,"기초") | P33: =COUNTIFS(과년도모음!$B$343:$B$1024,P$2,과년도모음!$E$343:$E$1024,"기초") | Q33: =COUNTIFS(과년도모음!$B$343:$B$1024,Q$2,과년도모음!$E$343:$E$1024,"기초") | R33: =COUNTIFS(과년도모음!$B$405:$B$1024,R$2,과년도모음!$E$405:$E$1024,"기초") | S33: =COUNTIFS(과년도모음!$B$405:$B$1024,S$2,과년도모음!$E$405:$E$1024,"기초") | T33: =COUNTIFS(과년도모음!$B$405:$B$1024,T$2,과년도모음!$E$405:$E$1024,"기초") | U33: =COUNTIFS(과년도모음!$B$405:$B$1024,U$2,과년도모음!$E$405:$E$1024,"기초") | V33: =COUNTIFS(과년도모음!$B$405:$B$1024,V$2,과년도모음!$E$405:$E$1024,"기초") | W33: =COUNTIFS(과년도모음!$B$405:$B$1024,W$2,과년도모음!$E$405:$E$1024,"기초") | X33: =COUNTIFS(과년도모음!$B$405:$B$1024,X$2,과년도모음!$E$405:$E$1024,"기초") | Y33: =COUNTIFS(과년도모음!$B$405:$B$1024,Y$2,과년도모음!$E$405:$E$1024,"기초") | ... AK33: =COUNTIFS(과년도모음!$B$405:$B$1024,AK$2,과년도모음!$E$405:$E$1024,"기초")
A34: =RANK(E34,$E$28:$E$48) | B34: 토공 | C34: =E34/$E$49 | D34: =E34/22 | E34: =SUM(F34:AK34) | F34: =COUNTIFS(과년도모음!$B$1:$B$1024,F$2,과년도모음!$E$1:$E$1024,"토공") | G34: =COUNTIFS(과년도모음!$B$1:$B$1024,G$2,과년도모음!$E$1:$E$1024,"토공") | H34: =COUNTIFS(과년도모음!$B$1:$B$1024,H$2,과년도모음!$E$1:$E$1024,"토공") | I34: =COUNTIFS(과년도모음!$B$1:$B$1024,I$2,과년도모음!$E$1:$E$1024,"토공") | J34: =COUNTIFS(과년도모음!$B$1:$B$1024,J$2,과년도모음!$E$1:$E$1024,"토공") | K34: =COUNTIFS(과년도모음!$B$1:$B$1024,K$2,과년도모음!$E$1:$E$1024,"토공") | L34: =COUNTIFS(과년도모음!$B$1:$B$1024,L$2,과년도모음!$E$1:$E$1024,"토공") | M34: =COUNTIFS(과년도모음!$B$1:$B$1024,M$2,과년도모음!$E$1:$E$1024,"토공") | N34: =COUNTIFS(과년도모음!$B$281:$B$1024,N$2,과년도모음!$E$281:$E$1024,"토공") | O34: =COUNTIFS(과년도모음!$B$312:$B$1024,O$2,과년도모음!$E$312:$E$1024,"토공") | P34: =COUNTIFS(과년도모음!$B$343:$B$1024,P$2,과년도모음!$E$343:$E$1024,"토공") | Q34: =COUNTIFS(과년도모음!$B$343:$B$1024,Q$2,과년도모음!$E$343:$E$1024,"토공") | R34: =COUNTIFS(과년도모음!$B$405:$B$1024,R$2,과년도모음!$E$405:$E$1024,"토공") | S34: =COUNTIFS(과년도모음!$B$405:$B$1024,S$2,과년도모음!$E$405:$E$1024,"토공") | T34: =COUNTIFS(과년도모음!$B$405:$B$1024,T$2,과년도모음!$E$405:$E$1024,"토공") | U34: =COUNTIFS(과년도모음!$B$405:$B$1024,U$2,과년도모음!$E$405:$E$1024,"토공") | V34: =COUNTIFS(과년도모음!$B$405:$B$1024,V$2,과년도모음!$E$405:$E$1024,"토공") | W34: =COUNTIFS(과년도모음!$B$405:$B$1024,W$2,과년도모음!$E$405:$E$1024,"토공") | X34: =COUNTIFS(과년도모음!$B$405:$B$1024,X$2,과년도모음!$E$405:$E$1024,"토공") | Y34: =COUNTIFS(과년도모음!$B$405:$B$1024,Y$2,과년도모음!$E$405:$E$1024,"토공") | ... AK34: =COUNTIFS(과년도모음!$B$405:$B$1024,AK$2,과년도모음!$E$405:$E$1024,"토공")
A35: =RANK(E35,$E$28:$E$48) | B35: 시설물안전법 | C35: =E35/$E$49 | D35: =E35/22 | E35: =SUM(F35:AK35) | F35: =COUNTIFS(과년도모음!$B$1:$B$1024,F$2,과년도모음!$E$1:$E$1024,"시설물안전법") | G35: =COUNTIFS(과년도모음!$B$1:$B$1024,G$2,과년도모음!$E$1:$E$1024,"시설물안전법") | H35: =COUNTIFS(과년도모음!$B$1:$B$1024,H$2,과년도모음!$E$1:$E$1024,"시설물안전법") | I35: =COUNTIFS(과년도모음!$B$1:$B$1024,I$2,과년도모음!$E$1:$E$1024,"시설물안전법") | J35: =COUNTIFS(과년도모음!$B$1:$B$1024,J$2,과년도모음!$E$1:$E$1024,"시설물안전법") | K35: =COUNTIFS(과년도모음!$B$1:$B$1024,K$2,과년도모음!$E$1:$E$1024,"시설물안전법") | L35: =COUNTIFS(과년도모음!$B$1:$B$1024,L$2,과년도모음!$E$1:$E$1024,"시설물안전법") | M35: =COUNTIFS(과년도모음!$B$1:$B$1024,M$2,과년도모음!$E$1:$E$1024,"시설물안전법") | N35: =COUNTIFS(과년도모음!$B$281:$B$1024,N$2,과년도모음!$E$281:$E$1024,"시설물안전법") | O35: =COUNTIFS(과년도모음!$B$312:$B$1024,O$2,과년도모음!$E$312:$E$1024,"시설물안전법") | P35: =COUNTIFS(과년도모음!$B$343:$B$1024,P$2,과년도모음!$E$343:$E$1024,"시설물안전법") | Q35: =COUNTIFS(과년도모음!$B$343:$B$1024,Q$2,과년도모음!$E$343:$E$1024,"시설물안전법") | R35: =COUNTIFS(과년도모음!$B$405:$B$1024,R$2,과년도모음!$E$405:$E$1024,"시설물안전법") | S35: =COUNTIFS(과년도모음!$B$405:$B$1024,S$2,과년도모음!$E$405:$E$1024,"시설물안전법") | T35: =COUNTIFS(과년도모음!$B$405:$B$1024,T$2,과년도모음!$E$405:$E$1024,"시설물안전법") | U35: =COUNTIFS(과년도모음!$B$405:$B$1024,U$2,과년도모음!$E$405:$E$1024,"시설물안전법") | V35: =COUNTIFS(과년도모음!$B$405:$B$1024,V$2,과년도모음!$E$405:$E$1024,"시설물안전법") | W35: =COUNTIFS(과년도모음!$B$405:$B$1024,W$2,과년도모음!$E$405:$E$1024,"시설물안전법") | X35: =COUNTIFS(과년도모음!$B$405:$B$1024,X$2,과년도모음!$E$405:$E$1024,"시설물안전법") | Y35: =COUNTIFS(과년도모음!$B$405:$B$1024,Y$2,과년도모음!$E$405:$E$1024,"시설물안전법") | ... AK35: =COUNTIFS(과년도모음!$B$405:$B$1024,AK$2,과년도모음!$E$405:$E$1024,"시설물안전법")
A36: =RANK(E36,$E$28:$E$48) | B36: 건설기술진흥법 | C36: =E36/$E$49 | D36: =E36/22 | E36: =SUM(F36:AK36) | F36: =COUNTIFS(과년도모음!$B$1:$B$1024,F$2,과년도모음!$E$1:$E$1024,"건진법") | G36: =COUNTIFS(과년도모음!$B$1:$B$1024,G$2,과년도모음!$E$1:$E$1024,"건진법") | H36: =COUNTIFS(과년도모음!$B$1:$B$1024,H$2,과년도모음!$E$1:$E$1024,"건진법") | I36: =COUNTIFS(과년도모음!$B$1:$B$1024,I$2,과년도모음!$E$1:$E$1024,"건진법") | J36: =COUNTIFS(과년도모음!$B$1:$B$1024,J$2,과년도모음!$E$1:$E$1024,"건진법") | K36: =COUNTIFS(과년도모음!$B$1:$B$1024,K$2,과년도모음!$E$1:$E$1024,"건진법") | L36: =COUNTIFS(과년도모음!$B$1:$B$1024,L$2,과년도모음!$E$1:$E$1024,"건진법") | M36: =COUNTIFS(과년도모음!$B$1:$B$1024,M$2,과년도모음!$E$1:$E$1024,"건진법") | N36: =COUNTIFS(과년도모음!$B$281:$B$1024,N$2,과년도모음!$E$281:$E$1024,"건진법") | O36: =COUNTIFS(과년도모음!$B$312:$B$1024,O$2,과년도모음!$E$312:$E$1024,"건진법") | P36: =COUNTIFS(과년도모음!$B$343:$B$1024,P$2,과년도모음!$E$343:$E$1024,"건진법") | Q36: =COUNTIFS(과년도모음!$B$343:$B$1024,Q$2,과년도모음!$E$343:$E$1024,"건진법") | R36: =COUNTIFS(과년도모음!$B$405:$B$1024,R$2,과년도모음!$E$405:$E$1024,"건진법") | S36: =COUNTIFS(과년도모음!$B$405:$B$1024,S$2,과년도모음!$E$405:$E$1024,"건진법") | T36: =COUNTIFS(과년도모음!$B$405:$B$1024,T$2,과년도모음!$E$405:$E$1024,"건진법") | U36: =COUNTIFS(과년도모음!$B$405:$B$1024,U$2,과년도모음!$E$405:$E$1024,"건진법") | V36: =COUNTIFS(과년도모음!$B$405:$B$1024,V$2,과년도모음!$E$405:$E$1024,"건진법") | W36: =COUNTIFS(과년도모음!$B$405:$B$1024,W$2,과년도모음!$E$405:$E$1024,"건진법") | X36: =COUNTIFS(과년도모음!$B$405:$B$1024,X$2,과년도모음!$E$405:$E$1024,"건진법") | Y36: =COUNTIFS(과년도모음!$B$405:$B$1024,Y$2,과년도모음!$E$405:$E$1024,"건진법") | ... AK36: =COUNTIFS(과년도모음!$B$405:$B$1024,AK$2,과년도모음!$E$405:$E$1024,"건진법")
A37: =RANK(E37,$E$28:$E$48) | B37: 재해유형 | C37: =E37/$E$49 | D37: =E37/22 | E37: =SUM(F37:AK37) | F37: =COUNTIFS(과년도모음!$B$1:$B$1024,F$2,과년도모음!$E$1:$E$1024,"재해유형") | G37: =COUNTIFS(과년도모음!$B$1:$B$1024,G$2,과년도모음!$E$1:$E$1024,"재해유형") | H37: =COUNTIFS(과년도모음!$B$1:$B$1024,H$2,과년도모음!$E$1:$E$1024,"재해유형") | I37: =COUNTIFS(과년도모음!$B$1:$B$1024,I$2,과년도모음!$E$1:$E$1024,"재해유형") | J37: =COUNTIFS(과년도모음!$B$1:$B$1024,J$2,과년도모음!$E$1:$E$1024,"재해유형") | K37: =COUNTIFS(과년도모음!$B$1:$B$1024,K$2,과년도모음!$E$1:$E$1024,"재해유형") | L37: =COUNTIFS(과년도모음!$B$1:$B$1024,L$2,과년도모음!$E$1:$E$1024,"재해유형") | M37: =COUNTIFS(과년도모음!$B$1:$B$1024,M$2,과년도모음!$E$1:$E$1024,"재해유형") | N37: =COUNTIFS(과년도모음!$B$281:$B$1024,N$2,과년도모음!$E$281:$E$1024,"재해유형") | O37: =COUNTIFS(과년도모음!$B$312:$B$1024,O$2,과년도모음!$E$312:$E$1024,"재해유형") | P37: =COUNTIFS(과년도모음!$B$343:$B$1024,P$2,과년도모음!$E$343:$E$1024,"재해유형") | Q37: =COUNTIFS(과년도모음!$B$343:$B$1024,Q$2,과년도모음!$E$343:$E$1024,"재해유형") | R37: =COUNTIFS(과년도모음!$B$405:$B$1024,R$2,과년도모음!$E$405:$E$1024,"재해유형") | S37: =COUNTIFS(과년도모음!$B$405:$B$1024,S$2,과년도모음!$E$405:$E$1024,"재해유형") | T37: =COUNTIFS(과년도모음!$B$405:$B$1024,T$2,과년도모음!$E$405:$E$1024,"재해유형") | U37: =COUNTIFS(과년도모음!$B$405:$B$1024,U$2,과년도모음!$E$405:$E$1024,"재해유형") | V37: =COUNTIFS(과년도모음!$B$405:$B$1024,V$2,과년도모음!$E$405:$E$1024,"재해유형") | W37: =COUNTIFS(과년도모음!$B$405:$B$1024,W$2,과년도모음!$E$405:$E$1024,"재해유형") | X37: =COUNTIFS(과년도모음!$B$405:$B$1024,X$2,과년도모음!$E$405:$E$1024,"재해유형") | Y37: =COUNTIFS(과년도모음!$B$405:$B$1024,Y$2,과년도모음!$E$405:$E$1024,"재해유형") | ... AK37: =COUNTIFS(과년도모음!$B$405:$B$1024,AK$2,과년도모음!$E$405:$E$1024,"재해유형")
A38: =RANK(E38,$E$28:$E$48) | B38: 강재 및 철골 | C38: =E38/$E$49 | D38: =E38/22 | E38: =SUM(F38:AK38) | F38: =COUNTIFS(과년도모음!$B$1:$B$1024,F$2,과년도모음!$E$1:$E$1024,"강재")+COUNTIFS(과년도모음!$B$1:$B$1024,F27,과년도모음!$E$1:$E$1024,"철골") | G38: =COUNTIFS(과년도모음!$B$1:$B$1024,G$2,과년도모음!$E$1:$E$1024,"강재")+COUNTIFS(과년도모음!$B$1:$B$1024,G27,과년도모음!$E$1:$E$1024,"철골") | H38: =COUNTIFS(과년도모음!$B$1:$B$1024,H$2,과년도모음!$E$1:$E$1024,"강재")+COUNTIFS(과년도모음!$B$1:$B$1024,H27,과년도모음!$E$1:$E$1024,"철골") | I38: =COUNTIFS(과년도모음!$B$1:$B$1024,I$2,과년도모음!$E$1:$E$1024,"강재")+COUNTIFS(과년도모음!$B$1:$B$1024,I27,과년도모음!$E$1:$E$1024,"철골") | J38: =COUNTIFS(과년도모음!$B$1:$B$1024,J$2,과년도모음!$E$1:$E$1024,"강재")+COUNTIFS(과년도모음!$B$1:$B$1024,J27,과년도모음!$E$1:$E$1024,"철골") | K38: =COUNTIFS(과년도모음!$B$1:$B$1024,K$2,과년도모음!$E$1:$E$1024,"강재")+COUNTIFS(과년도모음!$B$1:$B$1024,K27,과년도모음!$E$1:$E$1024,"철골") | L38: =COUNTIFS(과년도모음!$B$1:$B$1024,L$2,과년도모음!$E$1:$E$1024,"강재")+COUNTIFS(과년도모음!$B$1:$B$1024,#REF!,과년도모음!$E$1:$E$1024,"철골") | M38: =COUNTIFS(과년도모음!$B$1:$B$1024,M$2,과년도모음!$E$1:$E$1024,"강재")+COUNTIFS(과년도모음!$B$1:$B$1024,#REF!,과년도모음!$E$1:$E$1024,"철골") | N38: =COUNTIFS(과년도모음!$B$281:$B$1024,N$2,과년도모음!$E$281:$E$1024,"강재")+COUNTIFS(과년도모음!$B$281:$B$1024,#REF!,과년도모음!$E$281:$E$1024,"철골") | O38: =COUNTIFS(과년도모음!$B$312:$B$1024,O$2,과년도모음!$E$312:$E$1024,"강재")+COUNTIFS(과년도모음!$B$312:$B$1024,#REF!,과년도모음!$E$312:$E$1024,"철골") | P38: =COUNTIFS(과년도모음!$B$343:$B$1024,P$2,과년도모음!$E$343:$E$1024,"강재")+COUNTIFS(과년도모음!$B$343:$B$1024,#REF!,과년도모음!$E$343:$E$1024,"철골") | Q38: =COUNTIFS(과년도모음!$B$343:$B$1024,Q$2,과년도모음!$E$343:$E$1024,"강재")+COUNTIFS(과년도모음!$B$343:$B$1024,#REF!,과년도모음!$E$343:$E$1024,"철골") | R38: =COUNTIFS(과년도모음!$B$405:$B$1024,R$2,과년도모음!$E$405:$E$1024,"강재")+COUNTIFS(과년도모음!$B$405:$B$1024,R$27,과년도모음!$E$405:$E$1024,"철골") | S38: =COUNTIFS(과년도모음!$B$405:$B$1024,S$2,과년도모음!$E$405:$E$1024,"강재")+COUNTIFS(과년도모음!$B$405:$B$1024,S$27,과년도모음!$E$405:$E$1024,"철골") | T38: =COUNTIFS(과년도모음!$B$405:$B$1024,T$2,과년도모음!$E$405:$E$1024,"강재")+COUNTIFS(과년도모음!$B$405:$B$1024,T$27,과년도모음!$E$405:$E$1024,"철골") | U38: =COUNTIFS(과년도모음!$B$405:$B$1024,U$2,과년도모음!$E$405:$E$1024,"강재")+COUNTIFS(과년도모음!$B$405:$B$1024,U$27,과년도모음!$E$405:$E$1024,"철골") | V38: =COUNTIFS(과년도모음!$B$405:$B$1024,V$2,과년도모음!$E$405:$E$1024,"강재")+COUNTIFS(과년도모음!$B$405:$B$1024,V$27,과년도모음!$E$405:$E$1024,"철골") | W38: =COUNTIFS(과년도모음!$B$405:$B$1024,W$2,과년도모음!$E$405:$E$1024,"강재")+COUNTIFS(과년도모음!$B$405:$B$1024,W$27,과년도모음!$E$405:$E$1024,"철골") | X38: =COUNTIFS(과년도모음!$B$405:$B$1024,X$2,과년도모음!$E$405:$E$1024,"강재")+COUNTIFS(과년도모음!$B$405:$B$1024,X$27,과년도모음!$E$405:$E$1024,"철골") | Y38: =COUNTIFS(과년도모음!$B$405:$B$1024,Y$2,과년도모음!$E$405:$E$1024,"강재")+COUNTIFS(과년도모음!$B$405:$B$1024,Y$27,과년도모음!$E$405:$E$1024,"철골") | ... AG38: =COUNTIFS(과년도모음!$B$405:$B$1024,AG$2,과년도모음!$E$405:$E$1024,"강재")+COUNTIFS(과년도모음!$B$405:$B$1024,AG$27,과년도모음!$E$405:$E$1024,"철골") | AH38: =COUNTIFS(과년도모음!$B$405:$B$1024,AH$2,과년도모음!$E$405:$E$1024,"강재")+COUNTIFS(과년도모음!$B$405:$B$1024,#REF!,과년도모음!$E$405:$E$1024,"철골") | AI38: =COUNTIFS(과년도모음!$B$405:$B$1024,AI$2,과년도모음!$E$405:$E$1024,"강재")+COUNTIFS(과년도모음!$B$405:$B$1024,#REF!,과년도모음!$E$405:$E$1024,"철골") | AJ38: =COUNTIFS(과년도모음!$B$405:$B$1024,AJ$2,과년도모음!$E$405:$E$1024,"강재")+COUNTIFS(과년도모음!$B$405:$B$1024,AJ$27,과년도모음!$E$405:$E$1024,"철골") | AK38: =COUNTIFS(과년도모음!$B$405:$B$1024,AK$2,과년도모음!$E$405:$E$1024,"강재")+COUNTIFS(과년도모음!$B$405:$B$1024,AK$27,과년도모음!$E$405:$E$1024,"철골")
A39: =RANK(E39,$E$28:$E$48) | B39: 터널 | C39: =E39/$E$49 | D39: =E39/22 | E39: =SUM(F39:AK39) | F39: =COUNTIFS(과년도모음!$B$1:$B$1024,F$2,과년도모음!$E$1:$E$1024,"터널") | G39: =COUNTIFS(과년도모음!$B$1:$B$1024,G$2,과년도모음!$E$1:$E$1024,"터널") | H39: =COUNTIFS(과년도모음!$B$1:$B$1024,H$2,과년도모음!$E$1:$E$1024,"터널") | I39: =COUNTIFS(과년도모음!$B$1:$B$1024,I$2,과년도모음!$E$1:$E$1024,"터널") | J39: =COUNTIFS(과년도모음!$B$1:$B$1024,J$2,과년도모음!$E$1:$E$1024,"터널") | K39: =COUNTIFS(과년도모음!$B$1:$B$1024,K$2,과년도모음!$E$1:$E$1024,"터널") | L39: =COUNTIFS(과년도모음!$B$1:$B$1024,L$2,과년도모음!$E$1:$E$1024,"터널") | M39: =COUNTIFS(과년도모음!$B$1:$B$1024,M$2,과년도모음!$E$1:$E$1024,"터널") | N39: =COUNTIFS(과년도모음!$B$281:$B$1024,N$2,과년도모음!$E$281:$E$1024,"터널") | O39: =COUNTIFS(과년도모음!$B$312:$B$1024,O$2,과년도모음!$E$312:$E$1024,"터널") | P39: =COUNTIFS(과년도모음!$B$343:$B$1024,P$2,과년도모음!$E$343:$E$1024,"터널") | Q39: =COUNTIFS(과년도모음!$B$343:$B$1024,Q$2,과년도모음!$E$343:$E$1024,"터널") | R39: =COUNTIFS(과년도모음!$B$405:$B$1024,R$2,과년도모음!$E$405:$E$1024,"터널") | S39: =COUNTIFS(과년도모음!$B$405:$B$1024,S$2,과년도모음!$E$405:$E$1024,"터널") | T39: =COUNTIFS(과년도모음!$B$405:$B$1024,T$2,과년도모음!$E$405:$E$1024,"터널") | U39: =COUNTIFS(과년도모음!$B$405:$B$1024,U$2,과년도모음!$E$405:$E$1024,"터널") | V39: =COUNTIFS(과년도모음!$B$405:$B$1024,V$2,과년도모음!$E$405:$E$1024,"터널") | W39: =COUNTIFS(과년도모음!$B$405:$B$1024,W$2,과년도모음!$E$405:$E$1024,"터널") | X39: =COUNTIFS(과년도모음!$B$405:$B$1024,X$2,과년도모음!$E$405:$E$1024,"터널") | Y39: =COUNTIFS(과년도모음!$B$405:$B$1024,Y$2,과년도모음!$E$405:$E$1024,"터널") | ... AK39: =COUNTIFS(과년도모음!$B$405:$B$1024,AK$2,과년도모음!$E$405:$E$1024,"터널")
A40: =RANK(E40,$E$28:$E$48) | B40: 기타(댐 제방 항만) | C40: =E40/$E$49 | D40: =E40/22 | E40: =SUM(F40:AK40) | F40: =COUNTIFS(과년도모음!$B$1:$B$1024,F$2,과년도모음!$E$1:$E$1024,"제방 댐 항만")+COUNTIFS(과년도모음!$B$1:$B$1024,F$27,과년도모음!$E$1:$E$1024,"기타") | G40: =COUNTIFS(과년도모음!$B$1:$B$1024,G$2,과년도모음!$E$1:$E$1024,"제방 댐 항만")+COUNTIFS(과년도모음!$B$1:$B$1024,G$27,과년도모음!$E$1:$E$1024,"기타") | H40: =COUNTIFS(과년도모음!$B$1:$B$1024,H$2,과년도모음!$E$1:$E$1024,"제방 댐 항만")+COUNTIFS(과년도모음!$B$1:$B$1024,H$27,과년도모음!$E$1:$E$1024,"기타") | I40: =COUNTIFS(과년도모음!$B$1:$B$1024,I$2,과년도모음!$E$1:$E$1024,"제방 댐 항만")+COUNTIFS(과년도모음!$B$1:$B$1024,I$27,과년도모음!$E$1:$E$1024,"기타") | J40: =COUNTIFS(과년도모음!$B$1:$B$1024,J$2,과년도모음!$E$1:$E$1024,"제방 댐 항만")+COUNTIFS(과년도모음!$B$1:$B$1024,J$27,과년도모음!$E$1:$E$1024,"기타") | K40: =COUNTIFS(과년도모음!$B$1:$B$1024,K$2,과년도모음!$E$1:$E$1024,"제방 댐 항만")+COUNTIFS(과년도모음!$B$1:$B$1024,K$27,과년도모음!$E$1:$E$1024,"기타") | L40: =COUNTIFS(과년도모음!$B$1:$B$1024,L$2,과년도모음!$E$1:$E$1024,"제방 댐 항만")+COUNTIFS(과년도모음!$B$1:$B$1024,L$27,과년도모음!$E$1:$E$1024,"기타") | M40: =COUNTIFS(과년도모음!$B$1:$B$1024,M$2,과년도모음!$E$1:$E$1024,"제방 댐 항만")+COUNTIFS(과년도모음!$B$1:$B$1024,M$27,과년도모음!$E$1:$E$1024,"기타") | N40: =COUNTIFS(과년도모음!$B$281:$B$1024,N$2,과년도모음!$E$281:$E$1024,"제방 댐 항만")+COUNTIFS(과년도모음!$B$281:$B$1024,N$27,과년도모음!$E$281:$E$1024,"기타") | O40: =COUNTIFS(과년도모음!$B$312:$B$1024,O$2,과년도모음!$E$312:$E$1024,"제방 댐 항만")+COUNTIFS(과년도모음!$B$312:$B$1024,O$27,과년도모음!$E$312:$E$1024,"기타") | P40: =COUNTIFS(과년도모음!$B$343:$B$1024,P$2,과년도모음!$E$343:$E$1024,"제방 댐 항만")+COUNTIFS(과년도모음!$B$343:$B$1024,P$27,과년도모음!$E$343:$E$1024,"기타") | Q40: =COUNTIFS(과년도모음!$B$343:$B$1024,Q$2,과년도모음!$E$343:$E$1024,"제방 댐 항만")+COUNTIFS(과년도모음!$B$343:$B$1024,#REF!,과년도모음!$E$343:$E$1024,"기타") | R40: =COUNTIFS(과년도모음!$B$405:$B$1024,R$2,과년도모음!$E$405:$E$1024,"제방 댐 항만")+COUNTIFS(과년도모음!$B$405:$B$1024,R$27,과년도모음!$E$405:$E$1024,"기타") | S40: =COUNTIFS(과년도모음!$B$405:$B$1024,S$2,과년도모음!$E$405:$E$1024,"제방 댐 항만")+COUNTIFS(과년도모음!$B$405:$B$1024,S$27,과년도모음!$E$405:$E$1024,"기타") | T40: =COUNTIFS(과년도모음!$B$405:$B$1024,T$2,과년도모음!$E$405:$E$1024,"제방 댐 항만")+COUNTIFS(과년도모음!$B$405:$B$1024,T$27,과년도모음!$E$405:$E$1024,"기타") | U40: =COUNTIFS(과년도모음!$B$405:$B$1024,U$2,과년도모음!$E$405:$E$1024,"제방 댐 항만")+COUNTIFS(과년도모음!$B$405:$B$1024,U$27,과년도모음!$E$405:$E$1024,"기타") | V40: =COUNTIFS(과년도모음!$B$405:$B$1024,V$2,과년도모음!$E$405:$E$1024,"제방 댐 항만")+COUNTIFS(과년도모음!$B$405:$B$1024,V$27,과년도모음!$E$405:$E$1024,"기타") | W40: =COUNTIFS(과년도모음!$B$405:$B$1024,W$2,과년도모음!$E$405:$E$1024,"제방 댐 항만")+COUNTIFS(과년도모음!$B$405:$B$1024,W$27,과년도모음!$E$405:$E$1024,"기타") | X40: =COUNTIFS(과년도모음!$B$405:$B$1024,X$2,과년도모음!$E$405:$E$1024,"제방 댐 항만")+COUNTIFS(과년도모음!$B$405:$B$1024,X$27,과년도모음!$E$405:$E$1024,"기타") | Y40: =COUNTIFS(과년도모음!$B$405:$B$1024,Y$2,과년도모음!$E$405:$E$1024,"제방 댐 항만")+COUNTIFS(과년도모음!$B$405:$B$1024,Y$27,과년도모음!$E$405:$E$1024,"기타") | ... AG40: =COUNTIFS(과년도모음!$B$405:$B$1024,AG$2,과년도모음!$E$405:$E$1024,"제방 댐 항만")+COUNTIFS(과년도모음!$B$405:$B$1024,AG$27,과년도모음!$E$405:$E$1024,"기타") | AH40: =COUNTIFS(과년도모음!$B$405:$B$1024,AH$2,과년도모음!$E$405:$E$1024,"제방 댐 항만")+COUNTIFS(과년도모음!$B$405:$B$1024,#REF!,과년도모음!$E$405:$E$1024,"기타") | AI40: =COUNTIFS(과년도모음!$B$405:$B$1024,AI$2,과년도모음!$E$405:$E$1024,"제방 댐 항만")+COUNTIFS(과년도모음!$B$405:$B$1024,#REF!,과년도모음!$E$405:$E$1024,"기타") | AJ40: =COUNTIFS(과년도모음!$B$405:$B$1024,AJ$2,과년도모음!$E$405:$E$1024,"제방 댐 항만")+COUNTIFS(과년도모음!$B$405:$B$1024,AJ$27,과년도모음!$E$405:$E$1024,"기타") | AK40: =COUNTIFS(과년도모음!$B$405:$B$1024,AK$2,과년도모음!$E$405:$E$1024,"제방 댐 항만")+COUNTIFS(과년도모음!$B$405:$B$1024,AK$27,과년도모음!$E$405:$E$1024,"기타")
A41: =RANK(E41,$E$28:$E$48) | B41: 해체공사 | C41: =E41/$E$49 | D41: =E41/22 | E41: =SUM(F41:AK41) | F41: =COUNTIFS(과년도모음!$B$1:$B$1024,F$2,과년도모음!$E$1:$E$1024,"해체공사") | G41: =COUNTIFS(과년도모음!$B$1:$B$1024,G$2,과년도모음!$E$1:$E$1024,"해체공사") | H41: =COUNTIFS(과년도모음!$B$1:$B$1024,H$2,과년도모음!$E$1:$E$1024,"해체공사") | I41: =COUNTIFS(과년도모음!$B$1:$B$1024,I$2,과년도모음!$E$1:$E$1024,"해체공사") | J41: =COUNTIFS(과년도모음!$B$1:$B$1024,J$2,과년도모음!$E$1:$E$1024,"해체공사") | K41: =COUNTIFS(과년도모음!$B$1:$B$1024,K$2,과년도모음!$E$1:$E$1024,"해체공사") | L41: =COUNTIFS(과년도모음!$B$1:$B$1024,L$2,과년도모음!$E$1:$E$1024,"해체공사") | M41: =COUNTIFS(과년도모음!$B$1:$B$1024,M$2,과년도모음!$E$1:$E$1024,"해체공사") | N41: =COUNTIFS(과년도모음!$B$281:$B$1024,N$2,과년도모음!$E$281:$E$1024,"해체공사") | O41: =COUNTIFS(과년도모음!$B$312:$B$1024,O$2,과년도모음!$E$312:$E$1024,"해체공사") | P41: =COUNTIFS(과년도모음!$B$343:$B$1024,P$2,과년도모음!$E$343:$E$1024,"해체공사") | Q41: =COUNTIFS(과년도모음!$B$343:$B$1024,Q$2,과년도모음!$E$343:$E$1024,"해체공사") | R41: =COUNTIFS(과년도모음!$B$405:$B$1024,R$2,과년도모음!$E$405:$E$1024,"해체공사") | S41: =COUNTIFS(과년도모음!$B$405:$B$1024,S$2,과년도모음!$E$405:$E$1024,"해체공사") | T41: =COUNTIFS(과년도모음!$B$405:$B$1024,T$2,과년도모음!$E$405:$E$1024,"해체공사") | U41: =COUNTIFS(과년도모음!$B$405:$B$1024,U$2,과년도모음!$E$405:$E$1024,"해체공사") | V41: =COUNTIFS(과년도모음!$B$405:$B$1024,V$2,과년도모음!$E$405:$E$1024,"해체공사") | W41: =COUNTIFS(과년도모음!$B$405:$B$1024,W$2,과년도모음!$E$405:$E$1024,"해체공사") | X41: =COUNTIFS(과년도모음!$B$405:$B$1024,X$2,과년도모음!$E$405:$E$1024,"해체공사") | Y41: =COUNTIFS(과년도모음!$B$405:$B$1024,Y$2,과년도모음!$E$405:$E$1024,"해체공사") | ... AK41: =COUNTIFS(과년도모음!$B$405:$B$1024,AK$2,과년도모음!$E$405:$E$1024,"해체공사")
...

Sheet 과년도모음
A1: 구분 | B1: 회차 | C1: 교시 | D1: 번호 | E1: cat1 | F1: cat2 | G1: 문제
B2: 138 | C2: 1 | D2: 1 | E2: 산안법 | F2: 보호구 | G2: 1. 보호구의 정의 및 구비 조건
B3: 138 | C3: 1 | D3: 2 | E3: 안전관리론 | F3: 제임스리즌 불안전행동 | G3: 2. 제임스 리즌(James Reason)의 불안전 행동 유형 4가지
B4: 138 | C4: 1 | D4: 3 | E4: 산안법 | F4: 안전관리자 선임기준 | G4: 3. 「산업안전보건법」상 건설업에서의 공사금액별 안전관리자 선임 기준 및 업무
B5: 138 | C5: 1 | D5: 4 | E5: 토공 | F5: 표준관입시험 | G5: 4. 표준관입시험(SPT, Standard Penetration Test)
B6: 138 | C6: 1 | D6: 5 | E6: 기초 | F6: 잠함 굴착 준수사항 | G6: 5. 「산업안전보건기준에 관한 규칙」상 잠함 등 내부에서의 굴착 작업 시 준수사항
B7: 138 | C7: 1 | D7: 6 | E7: 건설기계 | F7: 와이어로프 | G7: 6. 와이어로프의 안전하중, 안전계수, 장력계수
B8: 138 | C8: 1 | D8: 7 | E8: 안전관리론 | F8: TBM | G8: 7. TBM(Tool Box Meeting)
B9: 138 | C9: 1 | D9: 8 | E9: 안전관리론 | F9: ECRS 원칙 | G9: 8. 작업환경 개선을 위한 ECRS(Eliminate, Combine, Rearrange, Simplify) 원칙
B10: 138 | C10: 1 | D10: 9 | E10: 콘크리트 | F10: 거푸집_갱폼 | G10: 9. 「산업안전보건기준에 관한 규칙」상 갱폼의 조립·이동·양중·해체 작업을 하는 경우 준수사항
B11: 138 | C11: 1 | D11: 10 | E11: 해체공사 | F11: 해체작업 공해저감 | G11: 10. 건설공사에서 해체 작업 시 공해 저감 대책
B12: 138 | C12: 1 | D12: 11 | E12: 가설공사 | F12: 이동식비계 | G12: 11. 「산업안전보건기준에 관한 규칙」상 이동식 비계를 조립하여 작업하는 경우 준수사항
B13: 138 | C13: 1 | D13: 12 | E13: 산안법 | F13: 설계안전보건대장 DFS | G13: 12. 설계안전보건대장과 설계안전성검토(DFS, Design for Safety)
